Workbook

Sheet 使用说明
A1: EcomCraft 开发总表 · 使用说明
A2: 这张表包含什么
A3: 功能总表 | B3: 48 项功能，按 6 个阶段排列，其中 MVP（A 平台底座、B 电商出图、C 易用与运维）27 项；“功能状态”根据开发任务自动计算，不用手填
A4: 开发任务 | B4: 52 个可直接交给 Claude Code 的任务（MVP 30 个），按“顺序”列执行；每个任务都有涉及文件、依赖、验收标准、测试方式和可直接粘贴的提示词
A5: 非开发事项 | B5: 需要你自己完成的事（选模型、委托做工作流、收集测试商品、准备测试环境等），部分开发任务依赖它们
A6: 竞品分析 | B6: 10 个竞品的优势、短板与对我们的启示，附来源链接
A7: 测试商品集 / 品类预设矩阵 | B7: 模板质量测试与品类调优的进度跟踪
A8: 阶段汇总 | B8: 各阶段功能数、任务完成情况与收入来源，自动计算
A9: 暂不做 | B9: 明确先不做的事情和原因
A10: 相关文档
A11: 架构与路线图 | B11: docs/EcomCraft Architecture.zh-CN.md（英文版 docs/EcomCraft Architecture.md）：产品定位、部署拓扑、分层架构、MVP 范围；功能编号与本表一致
A12: 局域网平台需求 | B12: docs/EcomCraft 局域网多服务器平台需求.zh-CN.md（英文版 docs/EcomCraft LAN Multi-Server Platform Requirements.md）：执行服务器、审核、调度、存储的详细需求
A13: 本表位置 | B13: docs/EcomCraft 开发总表.xlsx，随仓库提交到 dev 分支
A14: 填写约定
A15: 黄色单元格 | B15: 由你填写；“状态”列从下拉菜单选择（未开始 / 进行中 / 已完成 / 暂缓）
A16: 编号规则 | B16: F = 功能，T = 开发任务，N = 非开发事项，S = 痛点解决方案；编号不复用，合并或取消的项在备注中说明
A17: 用 Claude Code 开发的流程
A18: 第 1 步 | B18: 先做 T00：在仓库根目录建 CLAUDE.md，并用 @AGENTS.md 导入现有规则
A19: 第 2 步 | B19: 按“顺序”列一次只做一个任务；每个任务开一个新会话，避免上下文混在一起
A20: 第 3 步 | B20: 复制该任务的“Claude Code 提示词”粘贴进去；大多数提示词会让 Claude 先进入计划模式出方案，你看过确认后再让它写代码
A21: 第 4 步 | B21: Claude 完成后，按“测试方式”列自己验证；涉及 GPU 生成的效果必须实际跑一遍，涉及多机的要在两台电脑上验证
A22: 第 5 步 | B22: 验证通过后一个任务做一次提交（dev 分支），再把任务状态改为“已完成”
A23: 第 6 步 | B23: “依赖”列中的任务未完成前不要开始；N 开头的依赖是非开发事项
A24: 第 7 步 | B24: 每个任务涉及的文档都要中英文同步更新
A25: 注意事项
A26: 重新构建 | B26: 修改 src/Extensions/EcomCraft/ 的 C# 代码后，需按 AGENTS.md 重新构建扩展，否则会加载旧程序集
A27: 用户数据 | B27: 不要让 Claude 修改 Data/、Models/、Output/ 中的内容
A28: 规则变更 | B28: T08、T09、T29 会修改需求文档或 AGENTS.md 中的规则，务必自己审阅后再同意
A29: 范围变更 | B29: 先改架构文档和需求文档（中英文），再改本表，最后改代码

Sheet 功能总表
A1: 功能总表
A2: “功能状态”与“任务数”由开发任务表自动计算；负责人、备注由你填写。
A4: 编号 | B4: 阶段 | C4: 功能 | D4: 说明 | E4: 基础 / 关联代码 | F4: 优先级 | G4: 标签 | H4: 来源 | I4: 对应开发任务 | J4: 任务数 | K4: 功能状态 | L4: 负责人 | M4: 备注
A5: F28 | B5: MVP-A：平台底座 | C5: 局域网多服务器实测 | D5: 编译并在真实 ComfyUI 上验证已完成的步骤 1–3（执行服务器登记、工作流发现、审核与快照），补齐 V1–V3 结论 | E5: ExecutionServers.cs、WorkflowDiscovery.cs、WorkflowReview*.cs | F5: 高 | H5: 需求文档步骤 0–3 | I5: T33 | J5: =COUNTIF(开发任务!$D$5:$D$200,A5) | K5: =IF(J5=0,"—",IF(COUNTIFS(开发任务!$D$5:$D$200,A5,开发任务!$L$5:$L$200,"已完成")=J5,"已完成",IF(COUNTIFS(开发任务!$D$5:$D$200,A5,开发任务!$L$5:$L$200,"未开始")=J5,"未开始","进行中")))
A6: F29 | B6: MVP-A：平台底座 | C6: 调用与自动调度 | D6: 规则 1：分派到排队最少且具备所需节点和模型的执行服务器；执行方抽象预留云端类型（不实现） | E6: ExecutionServers.cs；新增 Studio/Generation/ | F6: 高 | H6: 需求文档步骤 4 | I6: T34 | J6: =COUNTIF(开发任务!$D$5:$D$200,A6) | K6: =IF(J6=0,"—",IF(COUNTIFS(开发任务!$D$5:$D$200,A6,开发任务!$L$5:$L$200,"已完成")=J6,"已完成",IF(COUNTIFS(开发任务!$D$5:$D$200,A6,开发任务!$L$5:$L$200,"未开始")=J6,"未开始","进行中"))) | M6: 原 F15（多机多显卡管理）已并入
A7: F30 | B7: MVP-A：平台底座 | C7: 队列、失败改派与画廊 | D7: 多服务器队列、掉线报失败并可改派、画廊显示实际执行服务器 | E7: studio.js、StudioApi.cs | F7: 高 | H7: 需求文档步骤 5 | I7: T35 | J7: =COUNTIF(开发任务!$D$5:$D$200,A7) | K7: =IF(J7=0,"—",IF(COUNTIFS(开发任务!$D$5:$D$200,A7,开发任务!$L$5:$L$200,"已完成")=J7,"已完成",IF(COUNTIFS(开发任务!$D$5:$D$200,A7,开发任务!$L$5:$L$200,"未开始")=J7,"未开始","进行中")))
A8: F31 | B8: MVP-A：平台底座 | C8: 多人登录与局域网部署 | D8: 账号登录、排队上限、防火墙、共享存储可见性与局域网 HTTPS 限制的部署指南 | E8: SwarmUI 账号系统；中英文部署文档 | F8: 高 | H8: 需求文档步骤 6 | I8: T36 | J8: =COUNTIF(开发任务!$D$5:$D$200,A8) | K8: =IF(J8=0,"—",IF(COUNTIFS(开发任务!$D$5:$D$200,A8,开发任务!$L$5:$L$200,"已完成")=J8,"已完成",IF(COUNTIFS(开发任务!$D$5:$D$200,A8,开发任务!$L$5:$L$200,"未开始")=J8,"未开始","进行中")))
A9: F32 | B9: MVP-A：平台底座 | C9: 作品存储位置 | D9: 作品库与导出位置可设为本机（默认）、NAS 或其他电脑的共享文件夹；先本地后同步；系统数据固定本机 | E9: 新增 Studio/Storage/ | F9: 高 | G9: 运营友好 | H9: 需求文档 R11（2026-10-27 讨论） | I9: T37 | J9: =COUNTIF(开发任务!$D$5:$D$200,A9) | K9: =IF(J9=0,"—",IF(COUNTIFS(开发任务!$D$5:$D$200,A9,开发任务!$L$5:$L$200,"已完成")=J9,"已完成",IF(COUNTIFS(开发任务!$D$5:$D$200,A9,开发任务!$L$5:$L$200,"未开始")=J9,"未开始","进行中")))
A10: F24 | B10: MVP-A：平台底座 | C10: 工作台中英文界面 | D10: 翻译表骨架，现有文字迁入并补齐英文；之后新功能直接双语开发 | E10: Studio/index.html、studio.js、languages/ | F10: 高 | G10: 海外必做 | H10: 海外市场分析 | I10: T22 | J10: =COUNTIF(开发任务!$D$5:$D$200,A10) | K10: =IF(J10=0,"—",IF(COUNTIFS(开发任务!$D$5:$D$200,A10,开发任务!$L$5:$L$200,"已完成")=J10,"已完成",IF(COUNTIFS(开发任务!$D$5:$D$200,A10,开发任务!$L$5:$L$200,"未开始")=J10,"未开始","进行中")))
A11: F01 | B11: MVP-B：电商出图 | C11: 电商场景模板 | D11: 模板 = 已发布审核快照 + 电商信息（中英文名称、示例图、适用平台、所属套图）；内置白底主图、场景图、细节图、模特或手持图 | E11: WorkflowReview.cs；新增 Studio/Templates/ | F11: 高 | H11: 功能规划；MVP 讨论 | I11: T01、T02、T04 | J11: =COUNTIF(开发任务!$D$5:$D$200,A11) | K11: =IF(J11=0,"—",IF(COUNTIFS(开发任务!$D$5:$D$200,A11,开发任务!$L$5:$L$200,"已完成")=J11,"已完成",IF(COUNTIFS(开发任务!$D$5:$D$200,A11,开发任务!$L$5:$L$200,"未开始")=J11,"未开始","进行中")))
A12: F37 | B12: MVP-B：电商出图 | C12: 提示词服务 | D12: 一句话描述（中英文）+ 风格 → MagicPrompt 优化成英文提示词；输出只作为提示词文本；看图描述默认关闭 | E12: MagicPrompt；新增 Studio/Prompting/ | F12: 高 | G12: 运营友好 | H12: MVP 讨论 | I12: T38 | J12: =COUNTIF(开发任务!$D$5:$D$200,A12) | K12: =IF(J12=0,"—",IF(COUNTIFS(开发任务!$D$5:$D$200,A12,开发任务!$L$5:$L$200,"已完成")=J12,"已完成",IF(COUNTIFS(开发任务!$D$5:$D$200,A12,开发任务!$L$5:$L$200,"未开始")=J12,"未开始","进行中")))
A13: F07 | B13: MVP-B：电商出图 | C13: 三步式简易模式 | D13: 默认界面：上传或选商品 → 选平台和风格 → 挑图下载；无提示词框；专业参数只对管理员可见 | E13: studio.js、index.html；新增 simple.js | F13: 高 | G13: 运营友好 | H13: 功能规划；MVP 讨论 | I13: T13 | J13: =COUNTIF(开发任务!$D$5:$D$200,A13) | K13: =IF(J13=0,"—",IF(COUNTIFS(开发任务!$D$5:$D$200,A13,开发任务!$L$5:$L$200,"已完成")=J13,"已完成",IF(COUNTIFS(开发任务!$D$5:$D$200,A13,开发任务!$L$5:$L$200,"未开始")=J13,"未开始","进行中")))
A14: F02 | B14: MVP-B：电商出图 | C14: 商品保真 | D14: 用商品蒙版把原商品像素合成回生成图，保证 Logo、文字、形状不被改动；合成始终在本地 | E14: ComfyUI 工作流 + 新增 Studio/PostProcess/ | F14: 高 | H14: 功能规划 | I14: T07 | J14: =COUNTIF(开发任务!$D$5:$D$200,A14) | K14: =IF(J14=0,"—",IF(COUNTIFS(开发任务!$D$5:$D$200,A14,开发任务!$L$5:$L$200,"已完成")=J14,"已完成",IF(COUNTIFS(开发任务!$D$5:$D$200,A14,开发任务!$L$5:$L$200,"未开始")=J14,"未开始","进行中")))
A15: F35 | B15: MVP-B：电商出图 | C15: 抠图确认与商品位置调整 | D15: 生成前确认抠图结果；可拖动和缩放商品在画面中的位置 | E15: Studio/PostProcess/；simple.js | F15: 高 | G15: 运营友好 | H15: MVP 讨论 | I15: T39 | J15: =COUNTIF(开发任务!$D$5:$D$200,A15) | K15: =IF(J15=0,"—",IF(COUNTIFS(开发任务!$D$5:$D$200,A15,开发任务!$L$5:$L$200,"已完成")=J15,"已完成",IF(COUNTIFS(开发任务!$D$5:$D$200,A15,开发任务!$L$5:$L$200,"未开始")=J15,"未开始","进行中")))
A16: F03 | B16: MVP-B：电商出图 | C16: 一键套图与批量 | D16: 按平台一次出整套图；多张商品排队；多台显卡并行；按人限流 | E16: 新增 Studio/Generation/ 编排 | F16: 高 | G16: 运营友好 | H16: 功能规划；MVP 讨论 | I16: T08 | J16: =COUNTIF(开发任务!$D$5:$D$200,A16) | K16: =IF(J16=0,"—",IF(COUNTIFS(开发任务!$D$5:$D$200,A16,开发任务!$L$5:$L$200,"已完成")=J16,"已完成",IF(COUNTIFS(开发任务!$D$5:$D$200,A16,开发任务!$L$5:$L$200,"未开始")=J16,"未开始","进行中")))
A17: F36 | B17: MVP-B：电商出图 | C17: 商品库（简版） | D17: 上传一次，缓存原图、抠图和位置，可重复用于不同平台的套图 | E17: 新增 Studio/Products/ | F17: 中 | G17: 运营友好 | H17: MVP 讨论 | I17: T40 | J17: =COUNTIF(开发任务!$D$5:$D$200,A17) | K17: =IF(J17=0,"—",IF(COUNTIFS(开发任务!$D$5:$D$200,A17,开发任务!$L$5:$L$200,"已完成")=J17,"已完成",IF(COUNTIFS(开发任务!$D$5:$D$200,A17,开发任务!$L$5:$L$200,"未开始")=J17,"未开始","进行中")))
A18: F05 | B18: MVP-B：电商出图 | C18: 平台导出 | D18: 国内外平台尺寸预设，自动缩放补边；下载 zip 或导出到共享文件夹 | E18: 新增 Studio/Export/ | F18: 高 | G18: 海外必做 | H18: 功能规划 | I18: T11 | J18: =COUNTIF(开发任务!$D$5:$D$200,A18) | K18: =IF(J18=0,"—",IF(COUNTIFS(开发任务!$D$5:$D$200,A18,开发任务!$L$5:$L$200,"已完成")=J18,"已完成",IF(COUNTIFS(开发任务!$D$5:$D$200,A18,开发任务!$L$5:$L$200,"未开始")=J18,"未开始","进行中")))
A19: F22 | B19: MVP-B：电商出图 | C19: 合规：亚马逊主图与 AI 元数据 | D19: 亚马逊白底主图走纯抠图分支（不调用生成模型）；导出写入 AI 生成元数据 | E19: Studio/Export/ + 模板分支 | F19: 高 | G19: 海外必做 | H19: 海外市场分析 | I19: T19 | J19: =COUNTIF(开发任务!$D$5:$D$200,A19) | K19: =IF(J19=0,"—",IF(COUNTIFS(开发任务!$D$5:$D$200,A19,开发任务!$L$5:$L$200,"已完成")=J19,"已完成",IF(COUNTIFS(开发任务!$D$5:$D$200,A19,开发任务!$L$5:$L$200,"未开始")=J19,"未开始","进行中")))
A20: F08 | B20: MVP-B：电商出图 | C20: 模型清单与商用许可标注 | D20: 按服务器列出模板缺少的模型和节点及商用许可状态；下载由管理员手动完成 | E20: 模板 requirements / license 字段 | F20: 中 | H20: 功能规划；痛点 S1 | I20: T14 | J20: =COUNTIF(开发任务!$D$5:$D$200,A20) | K20: =IF(J20=0,"—",IF(COUNTIFS(开发任务!$D$5:$D$200,A20,开发任务!$L$5:$L$200,"已完成")=J20,"已完成",IF(COUNTIFS(开发任务!$D$5:$D$200,A20,开发任务!$L$5:$L$200,"未开始")=J20,"未开始","进行中")))
A21: F20 | B21: MVP-B：电商出图 | C21: 模板测试台 | D21: 固定测试商品集 × 模板批量生成，输出报告，统计合格率，改参数后重跑对比 | E21: 调用平台生成 API 的 Node 脚本 | F21: 高 | H21: 痛点解决方案 S3 | I21: T06 | J21: =COUNTIF(开发任务!$D$5:$D$200,A21) | K21: =IF(J21=0,"—",IF(COUNTIFS(开发任务!$D$5:$D$200,A21,开发任务!$L$5:$L$200,"已完成")=J21,"已完成",IF(COUNTIFS(开发任务!$D$5:$D$200,A21,开发任务!$L$5:$L$200,"未开始")=J21,"未开始","进行中")))
A22: F10 | B22: MVP-C：易用与运维 | C22: 中英文 README 与演示 | D22: README 顶部效果对比图、演示视频、部署服务说明；中英文一致 | E22: README.md、README.en.md、docs 索引 | F22: 中 | G22: 海外必做 | H22: 功能规划 | I22: T16 | J22: =COUNTIF(开发任务!$D$5:$D$200,A22) | K22: =IF(J22=0,"—",IF(COUNTIFS(开发任务!$D$5:$D$200,A22,开发任务!$L$5:$L$200,"已完成")=J22,"已完成",IF(COUNTIFS(开发任务!$D$5:$D$200,A22,开发任务!$L$5:$L$200,"未开始")=J22,"未开始","进行中")))
A23: F38 | B23: MVP-C：易用与运维 | C23: 上传质量检查 | D23: 分辨率过低、模糊或商品占比过小时提前提醒，避免白跑显卡 | E23: simple.js；服务端检查 | F23: 中 | G23: 运营友好 | H23: MVP 讨论 | I23: T41 | J23: =COUNTIF(开发任务!$D$5:$D$200,A23) | K23: =IF(J23=0,"—",IF(COUNTIFS(开发任务!$D$5:$D$200,A23,开发任务!$L$5:$L$200,"已完成")=J23,"已完成",IF(COUNTIFS(开发任务!$D$5:$D$200,A23,开发任务!$L$5:$L$200,"未开始")=J23,"未开始","进行中")))
A24: F39 | B24: MVP-C：易用与运维 | C24: 未选候选图自动清理 | D24: 未选中的候选图 N 天后清理，选中、下载或导出过的永久保留 | E24: Studio/Storage/ | F24: 中 | H24: MVP 讨论 | I24: T42 | J24: =COUNTIF(开发任务!$D$5:$D$200,A24) | K24: =IF(J24=0,"—",IF(COUNTIFS(开发任务!$D$5:$D$200,A24,开发任务!$L$5:$L$200,"已完成")=J24,"已完成",IF(COUNTIFS(开发任务!$D$5:$D$200,A24,开发任务!$L$5:$L$200,"未开始")=J24,"未开始","进行中")))
A25: F40 | B25: MVP-C：易用与运维 | C25: 首次设置向导 | D25: 管理员首次进入：语言 → 存储位置 → 登记服务器 → 检查模型 → 选常用平台 | E25: 管理视图 | F25: 中 | G25: 运营友好 | H25: MVP 讨论 | I25: T44 | J25: =COUNTIF(开发任务!$D$5:$D$200,A25) | K25: =IF(J25=0,"—",IF(COUNTIFS(开发任务!$D$5:$D$200,A25,开发任务!$L$5:$L$200,"已完成")=J25,"已完成",IF(COUNTIFS(开发任务!$D$5:$D$200,A25,开发任务!$L$5:$L$200,"未开始")=J25,"未开始","进行中")))
A26: F41 | B26: MVP-C：易用与运维 | C26: 白话错误提示 | D26: 用运营看得懂的中英文说明原因和下一步 | E26: 错误码 + 翻译表 | F26: 中 | G26: 运营友好 | H26: MVP 讨论 | I26: T43 | J26: =COUNTIF(开发任务!$D$5:$D$200,A26) | K26: =IF(J26=0,"—",IF(COUNTIFS(开发任务!$D$5:$D$200,A26,开发任务!$L$5:$L$200,"已完成")=J26,"已完成",IF(COUNTIFS(开发任务!$D$5:$D$200,A26,开发任务!$L$5:$L$200,"未开始")=J26,"未开始","进行中")))
A27: F42 | B27: MVP-C：易用与运维 | C27: 手机拍照上传与移动端画廊 | D27: 手机拍照直接上传；手机浏览画廊；不依赖需要 HTTPS 的浏览器功能 | E27: studio.css、simple.js | F27: 中 | G27: 运营友好 | H27: MVP 讨论 | I27: T45 | J27: =COUNTIF(开发任务!$D$5:$D$200,A27) | K27: =IF(J27=0,"—",IF(COUNTIFS(开发任务!$D$5:$D$200,A27,开发任务!$L$5:$L$200,"已完成")=J27,"已完成",IF(COUNTIFS(开发任务!$D$5:$D$200,A27,开发任务!$L$5:$L$200,"未开始")=J27,"未开始","进行中")))
A28: F43 | B28: MVP-C：易用与运维 | C28: 完成通知 | D28: 批量任务完成或失败时页面内提醒，后台时标题显示进度 | E28: studio.js | F28: 低 | G28: 运营友好 | H28: MVP 讨论 | I28: T46 | J28: =COUNTIF(开发任务!$D$5:$D$200,A28) | K28: =IF(J28=0,"—",IF(COUNTIFS(开发任务!$D$5:$D$200,A28,开发任务!$L$5:$L$200,"已完成")=J28,"已完成",IF(COUNTIFS(开发任务!$D$5:$D$200,A28,开发任务!$L$5:$L$200,"未开始")=J28,"未开始","进行中")))
A29: F44 | B29: MVP-C：易用与运维 | C29: 一键诊断包 | D29: 打包日志、服务器状态和配置，不含密钥、提示词和图片，便于远程技术支持 | E29: 新增管理接口 | F29: 中 | H29: MVP 讨论 | I29: T47 | J29: =COUNTIF(开发任务!$D$5:$D$200,A29) | K29: =IF(J29=0,"—",IF(COUNTIFS(开发任务!$D$5:$D$200,A29,开发任务!$L$5:$L$200,"已完成")=J29,"已完成",IF(COUNTIFS(开发任务!$D$5:$D$200,A29,开发任务!$L$5:$L$200,"未开始")=J29,"未开始","进行中")))
A30: F45 | B30: MVP-C：易用与运维 | C30: 系统数据备份与升级 | D30: 一键备份与恢复系统数据；升级保留数据 | E30: 新增管理接口 | F30: 中 | H30: MVP 讨论 | I30: T48 | J30: =COUNTIF(开发任务!$D$5:$D$200,A30) | K30: =IF(J30=0,"—",IF(COUNTIFS(开发任务!$D$5:$D$200,A30,开发任务!$L$5:$L$200,"已完成")=J30,"已完成",IF(COUNTIFS(开发任务!$D$5:$D$200,A30,开发任务!$L$5:$L$200,"未开始")=J30,"未开始","进行中")))
A31: F46 | B31: MVP-C：易用与运维 | C31: 磁盘空间监控 | D31: 本机或共享存储空间不足时提醒管理员，严重不足时暂停接收任务 | E31: Studio/Storage/ | F31: 低 | H31: MVP 讨论 | I31: T49 | J31: =COUNTIF(开发任务!$D$5:$D$200,A31) | K31: =IF(J31=0,"—",IF(COUNTIFS(开发任务!$D$5:$D$200,A31,开发任务!$L$5:$L$200,"已完成")=J31,"已完成",IF(COUNTIFS(开发任务!$D$5:$D$200,A31,开发任务!$L$5:$L$200,"未开始")=J31,"未开始","进行中")))
A32: F25 | B32: 后续：功能增强 | C32: 卖点分析与套图分镜 | D32: 用提示词服务提炼卖点，生成整套图分镜，确认后批量生成 | E32: 提示词服务；依赖 F01、F03 | F32: 高 | H32: 竞品启发（EcomGen、ecommerce-image-suite） | I32: T30 | J32: =COUNTIF(开发任务!$D$5:$D$200,A32) | K32: =IF(J32=0,"—",IF(COUNTIFS(开发任务!$D$5:$D$200,A32,开发任务!$L$5:$L$200,"已完成")=J32,"已完成",IF(COUNTIFS(开发任务!$D$5:$D$200,A32,开发任务!$L$5:$L$200,"未开始")=J32,"未开始","进行中")))
A33: F19 | B33: 后续：功能增强 | C33: 品类预设 | D33: 每个模板按品类提供默认参数，调一次同品类通用 | E33: 依赖 F01 模板结构 | F33: 中 | H33: 痛点解决方案 S4 | I33: T05 | J33: =COUNTIF(开发任务!$D$5:$D$200,A33) | K33: =IF(J33=0,"—",IF(COUNTIFS(开发任务!$D$5:$D$200,A33,开发任务!$L$5:$L$200,"已完成")=J33,"已完成",IF(COUNTIFS(开发任务!$D$5:$D$200,A33,开发任务!$L$5:$L$200,"未开始")=J33,"未开始","进行中")))
A34: F12 | B34: 后续：功能增强 | C34: 品牌资料包 | D34: Logo、品牌色、偏好背景、风格参考图存成资料包，作为参考图和参数传给工作流 | E34: 依赖 F01 | F34: 中 | H34: 痛点调整 | I34: T17 | J34: =COUNTIF(开发任务!$D$5:$D$200,A34) | K34: =IF(J34=0,"—",IF(COUNTIFS(开发任务!$D$5:$D$200,A34,开发任务!$L$5:$L$200,"已完成")=J34,"已完成",IF(COUNTIFS(开发任务!$D$5:$D$200,A34,开发任务!$L$5:$L$200,"未开始")=J34,"未开始","进行中")))
A35: F04 | B35: 后续：功能增强 | C35: 项目归档与历史 | D35: 一个客户或一批商品即一个项目，作品可归档，支持用相同参数重做 | E35: 画廊与作品索引 | F35: 中 | H35: 功能规划 | I35: T09、T10 | J35: =COUNTIF(开发任务!$D$5:$D$200,A35) | K35: =IF(J35=0,"—",IF(COUNTIFS(开发任务!$D$5:$D$200,A35,开发任务!$L$5:$L$200,"已完成")=J35,"已完成",IF(COUNTIFS(开发任务!$D$5:$D$200,A35,开发任务!$L$5:$L$200,"未开始")=J35,"未开始","进行中")))
A36: F47 | B36: 后续：功能增强 | C36: 卖点图（固定版式文字） | D36: 按固定版式叠加用户填写的文字，文字由程序绘制，不由 AI 生成 | E36: 导出模块 | F36: 中 | G36: 运营友好 | H36: MVP 讨论 | I36: T50 | J36: =COUNTIF(开发任务!$D$5:$D$200,A36) | K36: =IF(J36=0,"—",IF(COUNTIFS(开发任务!$D$5:$D$200,A36,开发任务!$L$5:$L$200,"已完成")=J36,"已完成",IF(COUNTIFS(开发任务!$D$5:$D$200,A36,开发任务!$L$5:$L$200,"未开始")=J36,"未开始","进行中")))
A37: F48 | B37: 后续：功能增强 | C37: 商品展示视频 | D37: 商品展示视频模板及画廊、导出对视频的支持 | E37: 依赖 F01；N02 | F37: 中 | H37: 功能规划 | I37: T51 | J37: =COUNTIF(开发任务!$D$5:$D$200,A37) | K37: =IF(J37=0,"—",IF(COUNTIFS(开发任务!$D$5:$D$200,A37,开发任务!$L$5:$L$200,"已完成")=J37,"已完成",IF(COUNTIFS(开发任务!$D$5:$D$200,A37,开发任务!$L$5:$L$200,"未开始")=J37,"未开始","进行中")))
A38: F49 | B38: 后续：功能增强 | C38: 可见 AI 标识 | D38: 导出时可选加可见 AI 标识；导出含 AI 人物的作品清单 | E38: 导出模块 | F38: 中 | G38: 海外必做 | H38: 海外市场分析 | I38: T20 | J38: =COUNTIF(开发任务!$D$5:$D$200,A38) | K38: =IF(J38=0,"—",IF(COUNTIFS(开发任务!$D$5:$D$200,A38,开发任务!$L$5:$L$200,"已完成")=J38,"已完成",IF(COUNTIFS(开发任务!$D$5:$D$200,A38,开发任务!$L$5:$L$200,"未开始")=J38,"未开始","进行中")))
A39: F21 | B39: 后续：功能增强 | C39: 候选图自动筛选 | D39: 按商品保真度给候选打分，只展示合格结果 | E39: 依赖 F02 商品蒙版 | F39: 中 | H39: 痛点解决方案 S6 | I39: T18 | J39: =COUNTIF(开发任务!$D$5:$D$200,A39) | K39: =IF(J39=0,"—",IF(COUNTIFS(开发任务!$D$5:$D$200,A39,开发任务!$L$5:$L$200,"已完成")=J39,"已完成",IF(COUNTIFS(开发任务!$D$5:$D$200,A39,开发任务!$L$5:$L$200,"未开始")=J39,"未开始","进行中")))
A40: F06 | B40: 后续：功能增强 | C40: 前后对比图导出 | D40: 自动生成“原图 vs 成品”对比图 | E40: 前端画布生成 | F40: 低 | H40: 功能规划 | I40: T12 | J40: =COUNTIF(开发任务!$D$5:$D$200,A40) | K40: =IF(J40=0,"—",IF(COUNTIFS(开发任务!$D$5:$D$200,A40,开发任务!$L$5:$L$200,"已完成")=J40,"已完成",IF(COUNTIFS(开发任务!$D$5:$D$200,A40,开发任务!$L$5:$L$200,"未开始")=J40,"未开始","进行中")))
A41: F26 | B41: 后续：功能增强 | C41: PSD 分层导出 | D41: 商品层、背景层、文字层分层导出为 PSD | E41: 依赖 F02 商品蒙版 | F41: 低 | H41: 竞品启发（EcomGen） | I41: T31 | J41: =COUNTIF(开发任务!$D$5:$D$200,A41) | K41: =IF(J41=0,"—",IF(COUNTIFS(开发任务!$D$5:$D$200,A41,开发任务!$L$5:$L$200,"已完成")=J41,"已完成",IF(COUNTIFS(开发任务!$D$5:$D$200,A41,开发任务!$L$5:$L$200,"未开始")=J41,"未开始","进行中")))
...

Sheet 开发任务
A1: Claude Code 开发任务
A2: 按“顺序”执行；复制 K 列提示词到 Claude Code；状态从下拉选择。提示词已包含遵守 AGENTS.md 与架构文档、先出方案、中英文文档同步和完成后验证的要求。
A4: 顺序 | B4: 任务编号 | C4: 阶段 | D4: 功能编号 | E4: 任务 | F4: 涉及文件 / 模块 | G4: 依赖 | H4: 规模 | I4: 验收标准 | J4: 测试方式 | K4: Claude Code 提示词 | L4: 状态 | M4: 完成日期 | N4: 备注
A5: 1 | B5: T00 | C5: MVP-A：平台底座 | D5: 基础 | E5: 创建 CLAUDE.md 并导入 AGENTS.md | F5: CLAUDE.md（仓库根目录） | G5: — | H5: S | I5: Claude Code 启动时同时加载 CLAUDE.md 与 AGENTS.md；CLAUDE.md 写明常用命令、架构文档、需求文档和开发总表的位置以及中英文文档要求 | J5: 新开会话，询问本项目的 EcomCraft 规则和文档位置，应能正确回答 | K5: 请先阅读 AGENTS.md 和 docs/EcomCraft Architecture.zh-CN.md，遵守 EcomCraft 规则：客户端只提交模板 / 工作流 ID、服务端发布的参数白名单和各类 ID，不提交任意 ComfyUI JSON 或文件路径；生成只发往已登记的执行服务器（本机或局域网 ComfyUI），不向任何云端生成服务发送请求；接口遵守最小披露。用户可见文字走中英文翻译表；涉及的文档中英文同步更新。 任务：在仓库根目录创建 CLAUDE.md：第一行用 @AGENTS.md 导入现有规则；补充 EcomCraft 常用的构建与检查命令（先查看仓库中实际存在的脚本和测试，不要编造命令；注意 .gitignore 忽略了 Tests/ 目录）、“修改 C# 扩展后需按 AGENTS.md 重新构建扩展”的提醒，以及架构文档、需求文档和本开发总表（docs/EcomCraft 开发总表.xlsx）的位置。保持在 60 行以内，不要重复 AGENTS.md 已有内容。 完成后：运行相关测试，执行 git diff --check，按 ecomcraft-docs-sync 技能同步文档，并列出改动文件和你做过的验证。 | L5: 已完成 | M5: 2026-10-27
A6: 2 | B6: T33 | C6: MVP-A：平台底座 | D6: F28 | E6: 局域网多服务器实测（步骤 0–3） | F6: Studio/ExecutionServers.cs、WorkflowDiscovery.cs、WorkflowReview*.cs；需求文档第 9、10 节 | G6: T00；N08 | H6: M | I6: 扩展编译通过；A 能登记 B 并显示在线；B 上保存的工作流 1 分钟内进入待审核；审核通过后能在 B 上生成并回传；V1–V3 结论写入需求文档中英文版 | J6: 两台电脑实测，逐条对照需求文档 R1–R3 验收标准 | K6: 请先阅读 AGENTS.md 和 docs/EcomCraft Architecture.zh-CN.md，遵守 EcomCraft 规则：客户端只提交模板 / 工作流 ID、服务端发布的参数白名单和各类 ID，不提交任意 ComfyUI JSON 或文件路径；生成只发往已登记的执行服务器（本机或局域网 ComfyUI），不向任何云端生成服务发送请求；接口遵守最小披露。用户可见文字走中英文翻译表；涉及的文档中英文同步更新。 涉及局域网平台的需求以 docs/EcomCraft 局域网多服务器平台需求.zh-CN.md 为准，需求有变化先改该文档（中英文）。 任务：验证局域网多服务器第一阶段步骤 1–3（代码已完成但尚未编译和实测）。按 ecomcraft-build-run 技能编译并启动；按需求文档 R1–R3 的验收标准逐条验证；把 V1–V3 的实测结论和发现的问题写回需求文档（中英文）第 9、10 节。发现缺陷时先列出问题和修复方案，我确认后再改。 完成后：运行相关测试，执行 git diff --check，按 ecomcraft-docs-sync 技能同步文档，并列出改动文件和你做过的验证。 | L6: 进行中 | M6: 2026-10-27 | N6: 静态审查完成；两台电脑实测与 V1–V3 结论待 N08 测试环境
A7: 3 | B7: T34 | C7: MVP-A：平台底座 | D7: F29 | E7: 调用与自动调度（执行方抽象） | F7: Studio/ExecutionServers.cs、新增 Studio/Generation/、StudioApi.cs | G7: T33 | H7: L | I7: 按规则 1 选择排队最少且具备所需节点和模型的服务器；排队数计入他人直接提交到 ComfyUI 的任务；可限定服务器并在繁忙时提示；无可用服务器时说明原因；执行方抽象包含云端类型但不实现 | J7: C# 回归测试覆盖选择逻辑；两台电脑实测 | K7: 请先阅读 AGENTS.md 和 docs/EcomCraft Architecture.zh-CN.md，遵守 EcomCraft 规则：客户端只提交模板 / 工作流 ID、服务端发布的参数白名单和各类 ID，不提交任意 ComfyUI JSON 或文件路径；生成只发往已登记的执行服务器（本机或局域网 ComfyUI），不向任何云端生成服务发送请求；接口遵守最小披露。用户可见文字走中英文翻译表；涉及的文档中英文同步更新。 涉及局域网平台的需求以 docs/EcomCraft 局域网多服务器平台需求.zh-CN.md 为准，需求有变化先改该文档（中英文）。 任务：实现需求文档第一阶段步骤 4（R4、R5、R10.1）。调度按统一的“执行方”抽象实现，类型包含本机 ComfyUI、局域网 ComfyUI、云端 ComfyUI、云端模型 API；后两类只保留类型，不实现、不发任何请求。规则 1：筛选具备全部节点和模型的在线执行方，选排队最少者，排队数按 R5.2 计算。支持“只在某台服务器执行”和繁忙提示（R5.4）。 请先进入计划模式给出设计方案（改哪些文件、数据结构、接口、风险），我确认后再实现。 完成后：运行相关测试，执行 git diff --check，按 ecomcraft-docs-sync 技能同步文档，并列出改动文件和你做过的验证。 | L7: 已完成 | M7: 2026-10-27 | N7: 原 T26（多机多显卡）已并入本任务
A8: 4 | B8: T35 | C8: MVP-A：平台底座 | D8: F30 | E8: 队列、失败改派与画廊 | F8: studio.js、index.html、StudioApi.cs | G8: T34 | H8: M | I8: 执行中掉线直接报失败并提供改派按钮；画廊显示工作流名、实际执行服务器和时间；队列页显示每台服务器状态 | J8: 实测：生成过程中关闭 B 的 ComfyUI | K8: 请先阅读 AGENTS.md 和 docs/EcomCraft Architecture.zh-CN.md，遵守 EcomCraft 规则：客户端只提交模板 / 工作流 ID、服务端发布的参数白名单和各类 ID，不提交任意 ComfyUI JSON 或文件路径；生成只发往已登记的执行服务器（本机或局域网 ComfyUI），不向任何云端生成服务发送请求；接口遵守最小披露。用户可见文字走中英文翻译表；涉及的文档中英文同步更新。 涉及局域网平台的需求以 docs/EcomCraft 局域网多服务器平台需求.zh-CN.md 为准，需求有变化先改该文档（中英文）。 任务：完成需求文档步骤 5（R6、R7.1–R7.2、R8）。队列显示已部分完成，先核对现状再补齐：掉线报失败、“改派到其他服务器”按钮、画廊显示实际执行服务器。错误信息不得包含堆栈、地址、提示词或节点图。 请先进入计划模式给出设计方案（改哪些文件、数据结构、接口、风险），我确认后再实现。 完成后：运行相关测试，执行 git diff --check，按 ecomcraft-docs-sync 技能同步文档，并列出改动文件和你做过的验证。 | L8: 已完成 | M8: 2026-10-27
A9: 5 | B9: T36 | C9: MVP-A：平台底座 | D9: F31 | E9: 多人登录与局域网部署指南 | F9: 新增中英文部署文档；README.md、README.en.md、docs 索引 | G9: T35 | H9: M | I9: 部署文档说明账号登录、MaxQueued、防火墙、共享存储可见性和局域网 HTTPS 限制；中英文一致 | J9: 按文档在一台新电脑上从零部署一遍 | K9: 请先阅读 AGENTS.md 和 docs/EcomCraft Architecture.zh-CN.md，遵守 EcomCraft 规则：客户端只提交模板 / 工作流 ID、服务端发布的参数白名单和各类 ID，不提交任意 ComfyUI JSON 或文件路径；生成只发往已登记的执行服务器（本机或局域网 ComfyUI），不向任何云端生成服务发送请求；接口遵守最小披露。用户可见文字走中英文翻译表；涉及的文档中英文同步更新。 涉及局域网平台的需求以 docs/EcomCraft 局域网多服务器平台需求.zh-CN.md 为准，需求有变化先改该文档（中英文）。 任务：完成需求文档步骤 6（R9.1–R9.2 与安全要求）。编写局域网部署指南（中英文两份）：开启账号登录、按角色配置 MaxQueued、局域网服务器防火墙只对平台服务器开放 ComfyUI 端口、作品放在共享存储时的可见性（D9）、用 http 局域网地址访问时浏览器会禁用哪些功能。先检查 SwarmUI 现有的 Sharing Your Swarm 等文档能否引用，避免重复。 完成后：运行相关测试，执行 git diff --check，按 ecomcraft-docs-sync 技能同步文档，并列出改动文件和你做过的验证。 | L9: 已完成 | M9: 2026-10-27
A10: 6 | B10: T37 | C10: MVP-A：平台底座 | D10: F32 | E10: 作品存储位置（本机 / NAS / 共享文件夹） | F10: 新增 Studio/Storage/；管理设置界面 | G10: T35；N08 | H10: L | I10: 需求文档 R11 的验收标准全部通过 | J10: C# 测试路径校验与同步队列；实测：生成过程中断开 NAS | K10: 请先阅读 AGENTS.md 和 docs/EcomCraft Architecture.zh-CN.md，遵守 EcomCraft 规则：客户端只提交模板 / 工作流 ID、服务端发布的参数白名单和各类 ID，不提交任意 ComfyUI JSON 或文件路径；生成只发往已登记的执行服务器（本机或局域网 ComfyUI），不向任何云端生成服务发送请求；接口遵守最小披露。用户可见文字走中英文翻译表；涉及的文档中英文同步更新。 涉及局域网平台的需求以 docs/EcomCraft 局域网多服务器平台需求.zh-CN.md 为准，需求有变化先改该文档（中英文）。 任务：实现需求文档步骤 7（R11 作品存储）。作品库位置和导出位置由管理员设置（本机目录、UNC 路径、系统挂载目录），保存时检测可写、空间和速度；生成结果先写本机再后台同步，失败排队重试，画廊显示“待同步”；作品索引和缩略图留在本机；修改位置后旧作品仍可浏览，并提供可选迁移（复制、校验、再删除，可取消）。系统数据固定在 Data/。客户端不得提交路径。先调查 SwarmUI 现有 OutputPath 和画廊读取逻辑，尽量复用，不改核心。 请先进入计划模式给出设计方案（改哪些文件、数据结构、接口、风险），我确认后再实现。 完成后：运行相关测试，执行 git diff --check，按 ecomcraft-docs-sync 技能同步文档，并列出改动文件和你做过的验证。 | L10: 已完成 | M10: 2026-10-28
A11: 7 | B11: T22 | C11: MVP-A：平台底座 | D11: F24 | E11: 工作台中英文国际化 | F11: Studio/index.html、studio.js；新增 i18n.js、languages/ | G11: T00 | H11: L | I11: 工作台所有界面文字可在中文和英文间切换；新增文字必须走翻译表；英文模式下无残留中文 | J11: node 测试：英文模式下界面不残留中文字符串 | K11: 请先阅读 AGENTS.md 和 docs/EcomCraft Architecture.zh-CN.md，遵守 EcomCraft 规则：客户端只提交模板 / 工作流 ID、服务端发布的参数白名单和各类 ID，不提交任意 ComfyUI JSON 或文件路径；生成只发往已登记的执行服务器（本机或局域网 ComfyUI），不向任何云端生成服务发送请求；接口遵守最小披露。用户可见文字走中英文翻译表；涉及的文档中英文同步更新。 任务：为 EcomCraft 工作台建立中英文国际化。先调查 SwarmUI 现有 languages/ 与 translator.js 能否复用；建立翻译表和加载机制，把 index.html 与 studio.js 中现有中文文案迁入并补齐英文；语言选择记在浏览器（localStorage 读写放在 try/catch 中）。加一个测试：英文模式下界面不残留中文。在 ecomcraft-studio-ui 技能中补充“新文字必须走翻译表”的约定。 请先进入计划模式给出设计方案（改哪些文件、数据结构、接口、风险），我确认后再实现。 完成后：运行相关测试，执行 git diff --check，按 ecomcraft-docs-sync 技能同步文档，并列出改动文件和你做过的验证。 | L11: 已完成 | M11: 2026-10-28 | N11: 尽早完成，之后的新功能直接双语开发
A12: 8 | B12: T01 | C12: MVP-B：电商出图 | D12: F01 | E12: 模板数据结构（基于审核快照） | F12: 新增 Studio/Templates/；WorkflowReview.cs；EcomCraft.cs | G12: T34 | H12: M | I12: 模板只能引用已发布快照及其白名单参数；包含中英文名称、示例图、适用平台、所属套图，并预留 categories、brand_kit、execution_plans 字段；非法模板被拒绝并记录原因 | J12: C# 回归测试覆盖合法和非法模板 | K12: 请先阅读 AGENTS.md 和 docs/EcomCraft Architecture.zh-CN.md，遵守 EcomCraft 规则：客户端只提交模板 / 工作流 ID、服务端发布的参数白名单和各类 ID，不提交任意 ComfyUI JSON 或文件路径；生成只发往已登记的执行服务器（本机或局域网 ComfyUI），不向任何云端生成服务发送请求；接口遵守最小披露。用户可见文字走中英文翻译表；涉及的文档中英文同步更新。 任务：设计电商场景模板。模板 = 已发布的审核快照（WorkflowReview）+ 电商信息：中英文名称与说明、示例图、适用平台、所属套图、参数预设和提示词片段；预留 categories（品类预设）、brand_kit（品牌资料包）和 execution_plans（多个执行方案，本期只有本地方案）字段。不要另建一套与快照重复的工作流结构。内置模板与管理员自定义模板分开存放。补充一个无需 GPU 的 C# 回归测试。 请先进入计划模式给出设计方案（改哪些文件、数据结构、接口、风险），我确认后再实现。 完成后：运行相关测试，执行 git diff --check，按 ecomcraft-docs-sync 技能同步文档，并列出改动文件和你做过的验证。 | L12: 已完成 | M12: 2026-10-28
A13: 9 | B13: T02 | C13: MVP-B：电商出图 | D13: F01 | E13: 模板目录 API 与按模板生成 | F13: StudioApi.cs（新增 EcomCraftStudioTemplates，EcomCraftStudioGenerate 支持 template_id）；EcomCraft.cs | G13: T01 | H13: M | I13: 目录接口只返回模板 ID、名称、说明、示例图和可调字段；按 template_id 生成时用户输入仍经白名单校验；缺少依赖的模板被隐藏并给出原因 | J13: C# 回归测试 + 本机启动后调用接口 | K13: 请先阅读 AGENTS.md 和 docs/EcomCraft Architecture.zh-CN.md，遵守 EcomCraft 规则：客户端只提交模板 / 工作流 ID、服务端发布的参数白名单和各类 ID，不提交任意 ComfyUI JSON 或文件路径；生成只发往已登记的执行服务器（本机或局域网 ComfyUI），不向任何云端生成服务发送请求；接口遵守最小披露。用户可见文字走中英文翻译表；涉及的文档中英文同步更新。 任务：新增 API EcomCraftStudioTemplates（最小披露，按当前语言返回名称和说明），并让 EcomCraftStudioGenerate 支持 template_id：服务端把模板解析成快照与预设参数，再合并用户允许修改的字段，仍走现有白名单校验。没有执行服务器能运行该模板时，参照 WorkflowCatalogFilter 隐藏并说明原因。同步更新 README 中的接口列表和工作流文档。 请先进入计划模式给出设计方案（改哪些文件、数据结构、接口、风险），我确认后再实现。 完成后：运行相关测试，执行 git diff --check，按 ecomcraft-docs-sync 技能同步文档，并列出改动文件和你做过的验证。 | L13: 已完成 | M13: 2026-10-28
A14: 10 | B14: T38 | C14: MVP-B：电商出图 | D14: F37 | E14: 提示词服务（一句话描述 → 提示词） | F14: 新增 Studio/Prompting/；MagicPrompt | G14: T02 | H14: M | I14: 一句话描述（中英文均可）+ 风格 → 英文提示词；大模型输出只填入提示词文本字段；大模型不可用时退回模板默认提示词并提示；看图描述默认关闭，只有管理员可开启 | J14: C# 测试输出只进入提示词字段；用中文和英文描述各手动试一次 | K14: 请先阅读 AGENTS.md 和 docs/EcomCraft Architecture.zh-CN.md，遵守 EcomCraft 规则：客户端只提交模板 / 工作流 ID、服务端发布的参数白名单和各类 ID，不提交任意 ComfyUI JSON 或文件路径；生成只发往已登记的执行服务器（本机或局域网 ComfyUI），不向任何云端生成服务发送请求；接口遵守最小披露。用户可见文字走中英文翻译表；涉及的文档中英文同步更新。 任务：把 MagicPrompt 封装为提示词服务。输入：模板的提示词片段、用户选的风格、可选的一句话描述（中文或英文）；输出：英文提示词。大模型输出只能作为提示词文本，不得影响工作流、参数或执行服务器。设置超时；大模型不可用或超时时退回模板默认提示词并给出白话提示。把商品图发给在线视觉模型的功能默认关闭，只有管理员能开启，并在设置中明确说明图片会发送给哪家服务商。 请先进入计划模式给出设计方案（改哪些文件、数据结构、接口、风险），我确认后再实现。 完成后：运行相关测试，执行 git diff --check，按 ecomcraft-docs-sync 技能同步文档，并列出改动文件和你做过的验证。 | L14: 已完成 | M14: 2026-10-28
A15: 11 | B15: T13 | C15: MVP-B：电商出图 | D15: F07 | E15: 三步式简易模式（默认界面） | F15: Studio/index.html、studio.js、studio.css；新增 simple.js | G15: T02；T22；T38 | H15: L | I15: 默认界面为三步：上传或选择商品 → 选平台和风格 → 挑图下载；没有提示词框；风格为带示例图的选项；专业参数只对管理员可见；手机宽度可用 | J15: node 测试两种模式下的控件可见性；请一位不懂设计的同事试用 | K15: 请先阅读 AGENTS.md 和 docs/EcomCraft Architecture.zh-CN.md，遵守 EcomCraft 规则：客户端只提交模板 / 工作流 ID、服务端发布的参数白名单和各类 ID，不提交任意 ComfyUI JSON 或文件路径；生成只发往已登记的执行服务器（本机或局域网 ComfyUI），不向任何云端生成服务发送请求；接口遵守最小披露。用户可见文字走中英文翻译表；涉及的文档中英文同步更新。 任务：实现三步式简易模式，作为普通用户的默认界面：第 1 步上传商品图；第 2 步选平台、选风格（带示例图的卡片）、可选一句话描述；第 3 步查看候选图、挑选、下载。采样器、LoRA、步数等专业参数只在管理员的专业模式中出现。所有文字走翻译表；遵守现有 CSP（不引入外部脚本、不用内联脚本）；手机宽度可用。参照现有前端测试的 vm 方式加 node 测试。 请先进入计划模式给出设计方案（改哪些文件、数据结构、接口、风险），我确认后再实现。 完成后：运行相关测试，执行 git diff --check，按 ecomcraft-docs-sync 技能同步文档，并列出改动文件和你做过的验证。 | L15: 已完成 | M15: 2026-10-28 | N15: 原 T03（模板选择界面）已并入本任务
A16: 12 | B16: T07 | C16: MVP-B：电商出图 | D16: F02 | E16: 商品保真：原商品像素合成回生成图 | F16: 新增 Studio/PostProcess/；模板 preserve_product 标记；工作流需输出商品蒙版 | G16: T02；N02 | H16: L | I16: 开启 preserve_product 的模板，最终图中商品区域与原图像素一致（边缘羽化除外）；关闭时行为不变 | J16: C# 测试用合成图验证合成逻辑；用测试台人工比对 | K16: 请先阅读 AGENTS.md 和 docs/EcomCraft Architecture.zh-CN.md，遵守 EcomCraft 规则：客户端只提交模板 / 工作流 ID、服务端发布的参数白名单和各类 ID，不提交任意 ComfyUI JSON 或文件路径；生成只发往已登记的执行服务器（本机或局域网 ComfyUI），不向任何云端生成服务发送请求；接口遵守最小披露。用户可见文字走中英文翻译表；涉及的文档中英文同步更新。 涉及局域网平台的需求以 docs/EcomCraft 局域网多服务器平台需求.zh-CN.md 为准，需求有变化先改该文档（中英文）。 任务：为模板增加 preserve_product 选项。约定工作流额外输出商品蒙版。服务端在生成完成后用蒙版把原商品像素合成回生成图（边缘少量羽化），避免 Logo、文字、形状被改动。按“本地预处理 → 生成 → 本地后处理”三段设计（需求文档 R10.3），保证以后换成云端执行方时合成仍在本地。先调查 SwarmUI 现有的图片处理库与生成结果后处理挂钩点。 请先进入计划模式给出设计方案（改哪些文件、数据结构、接口、风险），我确认后再实现。 完成后：运行相关测试，执行 git diff --check，按 ecomcraft-docs-sync 技能同步文档，并列出改动文件和你做过的验证。 | L16: 已完成 | M16: 2026-10-28
A17: 13 | B17: T39 | C17: MVP-B：电商出图 | D17: F35 | E17: 抠图确认与商品位置调整 | F17: Studio/PostProcess/；simple.js | G17: T07；T13 | H17: M | I17: 生成前显示抠图结果，用户可确认或重新上传；可拖动和缩放商品在画面中的位置，合成按调整后的位置进行 | J17: node 测试位置换算；在电脑和手机上手动调整 | K17: 请先阅读 AGENTS.md 和 docs/EcomCraft Architecture.zh-CN.md，遵守 EcomCraft 规则：客户端只提交模板 / 工作流 ID、服务端发布的参数白名单和各类 ID，不提交任意 ComfyUI JSON 或文件路径；生成只发往已登记的执行服务器（本机或局域网 ComfyUI），不向任何云端生成服务发送请求；接口遵守最小披露。用户可见文字走中英文翻译表；涉及的文档中英文同步更新。 任务：在简易模式第 1 步后加入抠图确认：显示抠图结果（先调查执行服务器上可用的抠图节点或模型），用户确认或重新上传；允许拖动和缩放商品在画布中的位置与大小，最终合成按这个位置进行。客户端只提交位置和缩放数值，由服务端校验范围。 请先进入计划模式给出设计方案（改哪些文件、数据结构、接口、风险），我确认后再实现。 完成后：运行相关测试，执行 git diff --check，按 ecomcraft-docs-sync 技能同步文档，并列出改动文件和你做过的验证。 | L17: 已完成 | M17: 2026-10-28
A18: 14 | B18: T04 | C18: MVP-B：电商出图 | D18: F01 | E18: 内置 4 个电商场景模板 | F18: Studio/Templates/ 内置模板；中英文文档 | G18: T02；N02；N09 | H18: M | I18: 4 个模板通过校验；对应工作流未安装时显示“缺少工作流”而不是报错；名称和说明中英文齐全 | J18: C# 回归测试加载全部内置模板 | K18: 请先阅读 AGENTS.md 和 docs/EcomCraft Architecture.zh-CN.md，遵守 EcomCraft 规则：客户端只提交模板 / 工作流 ID、服务端发布的参数白名单和各类 ID，不提交任意 ComfyUI JSON 或文件路径；生成只发往已登记的执行服务器（本机或局域网 ComfyUI），不向任何云端生成服务发送请求；接口遵守最小披露。用户可见文字走中英文翻译表；涉及的文档中英文同步更新。 任务：新增 4 个内置模板定义：白底主图、场景图、细节图、模特或手持图（卖点图和视频留到后续）。工作流由外部专家制作，暂用约定的工作流名称占位；缺少工作流时隐藏并显示原因。为每个模板准备示例图位置。中英文文档同步说明模板用途。 完成后：运行相关测试，执行 git diff --check，按 ecomcraft-docs-sync 技能同步文档，并列出改动文件和你做过的验证。 | L18: 已完成 | M18: 2026-10-28 | N18: 原“卖点图”与“商品展示视频”移到后续（T50、T51）
A19: 15 | B19: T06 | C19: MVP-B：电商出图 | D19: F20 | E19: 模板测试台（批量跑分工具） | F19: 新增 src/Extensions/EcomCraft/Tools/template-bench（Node 脚本）；中英文说明 | G19: T04；N03 | H19: M | I19: 指定测试商品目录和模板列表后批量生成，输出结果图与带人工评分列的 CSV / HTML 报告；可与上次报告对比；不写入 Data/、Models/ | J19: 对本机服务运行一次小样本（2 个商品 × 1 个模板） | K19: 请先阅读 AGENTS.md 和 docs/EcomCraft Architecture.zh-CN.md，遵守 EcomCraft 规则：客户端只提交模板 / 工作流 ID、服务端发布的参数白名单和各类 ID，不提交任意 ComfyUI JSON 或文件路径；生成只发往已登记的执行服务器（本机或局域网 ComfyUI），不向任何云端生成服务发送请求；接口遵守最小披露。用户可见文字走中英文翻译表；涉及的文档中英文同步更新。 任务：写一个命令行模板测试台。输入：测试商品图目录、模板 ID 列表、平台服务地址。它依次调用按模板生成，把结果保存到用户指定的输出目录，并生成 CSV 和简单的 HTML 并排对比页，包含“合格 / 不合格 / 问题说明”空白列供人工打分；再次运行时可与上次报告对比。不得修改 Data/、Models/ 的内容。注意 .gitignore 忽略了 Tests/、tests/ 和 *-plan.md，命名时避开。 请先进入计划模式给出设计方案（改哪些文件、数据结构、接口、风险），我确认后再实现。 完成后：运行相关测试，执行 git diff --check，按 ecomcraft-docs-sync 技能同步文档，并列出改动文件和你做过的验证。 | L19: 已完成 | M19: 2026-10-28 | N19: 本机服务实测 2 商品 × 1 模板：结果、CSV/HTML 报告与 --compare 对比通过
A20: 16 | B20: T08 | C20: MVP-B：电商出图 | D20: F03 | E20: 一键套图与批量（多机并行、按人限流） | F20: 新增 Studio/Generation/ 编排；simple.js | G20: T13；T34 | H20: L | I20: 选平台后一张商品图出整套图；多张商品排队；任务由调度器分派到多台服务器并行；每人同时占用的任务数受限；单张失败可单独重试，可整体取消 | J20: C# 测试套图展开与限流；node 测试队列状态；两台电脑并行实测 | K20: 请先阅读 AGENTS.md 和 docs/EcomCraft Architecture.zh-CN.md，遵守 EcomCraft 规则：客户端只提交模板 / 工作流 ID、服务端发布的参数白名单和各类 ID，不提交任意 ComfyUI JSON 或文件路径；生成只发往已登记的执行服务器（本机或局域网 ComfyUI），不向任何云端生成服务发送请求；接口遵守最小披露。用户可见文字走中英文翻译表；涉及的文档中英文同步更新。 涉及局域网平台的需求以 docs/EcomCraft 局域网多服务器平台需求.zh-CN.md 为准，需求有变化先改该文档（中英文）。 任务：实现一键套图与批量（替代原先“并发为 1”的批量设计）。套图 = 平台对应的一组模板（如亚马逊：白底 + 场景 + 细节 + 模特），每种 N 张候选。服务端把套图和批量展开成任务，交给调度器多台并行；增加按人限流，避免一个人占满所有显卡（先在需求文档 R5 / R9 中补充规则，中英文同步）。前端显示每张图的状态，失败项可单独重试，可整体取消。 请先进入计划模式给出设计方案（改哪些文件、数据结构、接口、风险），我确认后再实现。 完成后：运行相关测试，执行 git diff --check，按 ecomcraft-docs-sync 技能同步文档，并列出改动文件和你做过的验证。 | L20: 已完成 | M20: 2026-10-28 | N20: 会修改需求文档规则，务必审阅
A21: 17 | B21: T40 | C21: MVP-B：电商出图 | D21: F36 | E21: 商品库（简版） | F21: 新增 Studio/Products/；simple.js | G21: T39；T37 | H21: M | I21: 上传的商品自动入库，保存原图和抠图结果；再次出图时可直接选择；平台内按用户隔离；可重命名和删除 | J21: C# 测试用户隔离与删除 | K21: 请先阅读 AGENTS.md 和 docs/EcomCraft Architecture.zh-CN.md，遵守 EcomCraft 规则：客户端只提交模板 / 工作流 ID、服务端发布的参数白名单和各类 ID，不提交任意 ComfyUI JSON 或文件路径；生成只发往已登记的执行服务器（本机或局域网 ComfyUI），不向任何云端生成服务发送请求；接口遵守最小披露。用户可见文字走中英文翻译表；涉及的文档中英文同步更新。 任务：实现简版商品库：商品图上传后保存原图、抠图结果和确认过的位置，平台内按用户隔离，用户可重命名和删除。出图时可从商品库选择，跳过上传和抠图。商品文件存放在作品库位置（R11），索引放在本机 Data/。客户端只提交商品 ID。 请先进入计划模式给出设计方案（改哪些文件、数据结构、接口、风险），我确认后再实现。 完成后：运行相关测试，执行 git diff --check，按 ecomcraft-docs-sync 技能同步文档，并列出改动文件和你做过的验证。 | L21: 已完成 | M21: 2026-10-28
A22: 18 | B22: T11 | C22: MVP-B：电商出图 | D22: F05 | E22: 平台导出（国内外预设、zip 或共享文件夹） | F22: 新增 Studio/Export/；平台预设配置文件；导出面板 | G22: T35；T37；N06 | H22: L | I22: 选择平台后自动按预设缩放和补边；按商品分文件夹打包 zip，或导出到共享文件夹；预设包含国内外平台和中英文名称，可在配置中修改 | J22: C# 测试尺寸与补边颜色（如纯白 RGB 255,255,255） | K22: 请先阅读 AGENTS.md 和 docs/EcomCraft Architecture.zh-CN.md，遵守 EcomCraft 规则：客户端只提交模板 / 工作流 ID、服务端发布的参数白名单和各类 ID，不提交任意 ComfyUI JSON 或文件路径；生成只发往已登记的执行服务器（本机或局域网 ComfyUI），不向任何云端生成服务发送请求；接口遵守最小披露。用户可见文字走中英文翻译表；涉及的文档中英文同步更新。 涉及局域网平台的需求以 docs/EcomCraft 局域网多服务器平台需求.zh-CN.md 为准，需求有变化先改该文档（中英文）。 任务：实现平台导出。平台预设放在可编辑的配置中，同时包含国内平台（淘宝 / 天猫、京东、拼多多、抖音等）和海外平台（亚马逊、Shopify、TikTok Shop 等）；先列出你打算使用的尺寸和规则并注明来源，让我确认。服务端按预设缩放、补边，按商品分文件夹打包 zip 下载，或写入管理员设置的导出位置（需求文档 R11.8）。 请先进入计划模式给出设计方案（改哪些文件、数据结构、接口、风险），我确认后再实现。 完成后：运行相关测试，执行 git diff --check，按 ecomcraft-docs-sync 技能同步文档，并列出改动文件和你做过的验证。 | L22: 已完成 | M22: 2026-10-28
A23: 19 | B23: T19 | C23: MVP-B：电商出图 | D23: F22 | E23: 合规：亚马逊主图模式与 AI 元数据 | F23: 内置模板分支；Studio/Export/ | G23: T04；T11；N06 | H23: M | I23: 亚马逊白底主图只抠图、居中、放到纯白背景，不调用生成模型；导出时检查背景纯白；AI 生成的图片导出时写入 AI 生成元数据 | J23: C# 测试背景像素检查与元数据写入 | K23: 请先阅读 AGENTS.md 和 docs/EcomCraft Architecture.zh-CN.md，遵守 EcomCraft 规则：客户端只提交模板 / 工作流 ID、服务端发布的参数白名单和各类 ID，不提交任意 ComfyUI JSON 或文件路径；生成只发往已登记的执行服务器（本机或局域网 ComfyUI），不向任何云端生成服务发送请求；接口遵守最小披露。用户可见文字走中英文翻译表；涉及的文档中英文同步更新。 任务：1）白底主图模板在平台为亚马逊时走“纯抠图”分支：只抠图、居中、放到纯白（RGB 255,255,255）背景，不调用任何生成模型；导出时检查背景是否纯白并提示。2）导出时为 AI 生成的图片写入标明 AI 生成的元数据。先列出打算写入的元数据字段及依据让我确认（开发前先完成 N06 核对最新规则）。可见 AI 标识留到后续（T20）。 请先进入计划模式给出设计方案（改哪些文件、数据结构、接口、风险），我确认后再实现。 完成后：运行相关测试，执行 git diff --check，按 ecomcraft-docs-sync 技能同步文档，并列出改动文件和你做过的验证。 | L23: 已完成 | M23: 2026-10-28
A24: 20 | B24: T14 | C24: MVP-B：电商出图 | D24: F08 | E24: 模型清单与商用许可标注 | F24: 模板增加 requirements 与 license 字段；管理视图 | G24: T02；N01 | H24: M | I24: 管理视图显示每个模板所需的模型和节点、每台服务器缺少哪些、每个模型的商用许可状态（允许 / 禁止 / 未知） | J24: C# 测试许可字段校验 | K24: 请先阅读 AGENTS.md 和 docs/EcomCraft Architecture.zh-CN.md，遵守 EcomCraft 规则：客户端只提交模板 / 工作流 ID、服务端发布的参数白名单和各类 ID，不提交任意 ComfyUI JSON 或文件路径；生成只发往已登记的执行服务器（本机或局域网 ComfyUI），不向任何云端生成服务发送请求；接口遵守最小披露。用户可见文字走中英文翻译表；涉及的文档中英文同步更新。 任务：模板声明所需模型和节点（requirements）以及每个模型的许可信息（commercial：allowed / forbidden / unknown 与许可链接）。管理视图按服务器列出缺失项和许可状态，许可为 forbidden 或 unknown 时显著提示。按需求文档假设 A2，模型由管理员手动安装，本任务不做跨服务器下载，只给出下载链接和安装位置说明。 请先进入计划模式给出设计方案（改哪些文件、数据结构、接口、风险），我确认后再实现。 完成后：运行相关测试，执行 git diff --check，按 ecomcraft-docs-sync 技能同步文档，并列出改动文件和你做过的验证。 | L24: 已完成 | M24: 2026-10-28
A25: 21 | B25: T41 | C25: MVP-C：易用与运维 | D25: F38 | E25: 上传质量检查 | F25: simple.js；服务端检查 | G25: T13 | H25: S | I25: 分辨率过低、模糊或商品占比过小时用白话提示原因和建议，用户可选择继续 | J25: node 测试阈值判断 | K25: 请先阅读 AGENTS.md 和 docs/EcomCraft Architecture.zh-CN.md，遵守 EcomCraft 规则：客户端只提交模板 / 工作流 ID、服务端发布的参数白名单和各类 ID，不提交任意 ComfyUI JSON 或文件路径；生成只发往已登记的执行服务器（本机或局域网 ComfyUI），不向任何云端生成服务发送请求；接口遵守最小披露。用户可见文字走中英文翻译表；涉及的文档中英文同步更新。 任务：上传商品图时检查分辨率、清晰度（如拉普拉斯方差）和抠图后的商品占比，不达标时用白话提示原因和建议（如“请拍得更近一些”），用户可以选择继续。阈值放在配置中。 完成后：运行相关测试，执行 git diff --check，按 ecomcraft-docs-sync 技能同步文档，并列出改动文件和你做过的验证。 | L25: 已完成 | M25: 2026-10-28
A26: 22 | B26: T42 | C26: MVP-C：易用与运维 | D26: F39 | E26: 未选候选图自动清理 | F26: Studio/Storage/ | G26: T37；T08 | H26: S | I26: 未被选中、下载或导出的候选图超过设定天数后自动清理；管理员可设置天数或关闭 | J26: C# 测试清理条件 | K26: 请先阅读 AGENTS.md 和 docs/EcomCraft Architecture.zh-CN.md，遵守 EcomCraft 规则：客户端只提交模板 / 工作流 ID、服务端发布的参数白名单和各类 ID，不提交任意 ComfyUI JSON 或文件路径；生成只发往已登记的执行服务器（本机或局域网 ComfyUI），不向任何云端生成服务发送请求；接口遵守最小披露。用户可见文字走中英文翻译表；涉及的文档中英文同步更新。 任务：实现未选候选图自动清理：记录每张候选是否被选中、下载或导出；未被使用的候选超过 N 天（默认 14 天，管理员可修改或关闭）后在后台删除，并更新作品索引。删除前再次确认文件位于作品库内，绝不删除作品库以外的文件。 请先进入计划模式给出设计方案（改哪些文件、数据结构、接口、风险），我确认后再实现。 完成后：运行相关测试，执行 git diff --check，按 ecomcraft-docs-sync 技能同步文档，并列出改动文件和你做过的验证。 | L26: 已完成 | M26: 2026-10-28
A27: 23 | B27: T43 | C27: MVP-C：易用与运维 | D27: F41 | E27: 白话错误提示 | F27: studio.js、翻译表；服务端错误码 | G27: T13 | H27: S | I27: 常见错误（无可用服务器、缺模型、上传格式、超时、存储离线等）都有中英文白话提示和下一步建议 | J27: node 测试错误码映射完整 | K27: 请先阅读 AGENTS.md 和 docs/EcomCraft Architecture.zh-CN.md，遵守 EcomCraft 规则：客户端只提交模板 / 工作流 ID、服务端发布的参数白名单和各类 ID，不提交任意 ComfyUI JSON 或文件路径；生成只发往已登记的执行服务器（本机或局域网 ComfyUI），不向任何云端生成服务发送请求；接口遵守最小披露。用户可见文字走中英文翻译表；涉及的文档中英文同步更新。 任务：整理 EcomCraft 接口的错误码，前端按错误码显示中英文白话提示和下一步建议（如“这台电脑缺少模特图需要的模型，请联系管理员”）。不得把异常堆栈、地址、提示词或节点图显示给用户。 完成后：运行相关测试，执行 git diff --check，按 ecomcraft-docs-sync 技能同步文档，并列出改动文件和你做过的验证。 | L27: 已完成 | M27: 2026-10-28
A28: 24 | B28: T44 | C28: MVP-C：易用与运维 | D28: F40 | E28: 首次设置向导 | F28: 管理视图 | G28: T37；T14；T22 | H28: M | I28: 管理员首次进入时依次完成：语言 → 存储位置 → 登记服务器 → 检查模型 → 选常用平台；每步可跳过，之后可重新打开 | J28: 在全新的数据目录上走一遍 | K28: 请先阅读 AGENTS.md 和 docs/EcomCraft Architecture.zh-CN.md，遵守 EcomCraft 规则：客户端只提交模板 / 工作流 ID、服务端发布的参数白名单和各类 ID，不提交任意 ComfyUI JSON 或文件路径；生成只发往已登记的执行服务器（本机或局域网 ComfyUI），不向任何云端生成服务发送请求；接口遵守最小披露。用户可见文字走中英文翻译表；涉及的文档中英文同步更新。 任务：为管理员实现首次设置向导：语言、作品存储位置、登记执行服务器（复用 SwarmUI 后端管理，不新建登记方式）、模型检查（复用 T14）、常用平台。每步可跳过，之后可在设置中重新打开。 请先进入计划模式给出设计方案（改哪些文件、数据结构、接口、风险），我确认后再实现。 完成后：运行相关测试，执行 git diff --check，按 ecomcraft-docs-sync 技能同步文档，并列出改动文件和你做过的验证。 | L28: 已完成 | M28: 2026-10-28 | N28: 全新数据目录的第二实例验证了向导各步数据源；界面走查可在部署时复查
A29: 25 | B29: T45 | C29: MVP-C：易用与运维 | D29: F42 | E29: 手机拍照上传与移动端画廊 | F29: studio.css、simple.js | G29: T13 | H29: M | I29: 手机浏览器能完成上传（含拍照）、出图和浏览画廊；不依赖需要 HTTPS 的浏览器功能 | J29: Android Chrome 与 iOS Safari 实测 | K29: 请先阅读 AGENTS.md 和 docs/EcomCraft Architecture.zh-CN.md，遵守 EcomCraft 规则：客户端只提交模板 / 工作流 ID、服务端发布的参数白名单和各类 ID，不提交任意 ComfyUI JSON 或文件路径；生成只发往已登记的执行服务器（本机或局域网 ComfyUI），不向任何云端生成服务发送请求；接口遵守最小披露。用户可见文字走中英文翻译表；涉及的文档中英文同步更新。 任务：让简易模式和画廊在手机上可用：上传使用 <input type=file accept=image/* capture>，在 http 局域网地址下也能拍照上传；画廊在窄屏下改为单列。不要使用需要安全上下文的 API（剪贴板读取、Notification 等）。 请先进入计划模式给出设计方案（改哪些文件、数据结构、接口、风险），我确认后再实现。 完成后：运行相关测试，执行 git diff --check，按 ecomcraft-docs-sync 技能同步文档，并列出改动文件和你做过的验证。 | L29: 进行中 | M29: 2026-10-28 | N29: 代码与自动检查完成；Android Chrome / iOS Safari 真机实测待做
A30: 26 | B30: T46 | C30: MVP-C：易用与运维 | D30: F43 | E30: 完成通知 | F30: studio.js | G30: T08 | H30: S | I30: 批量任务完成或失败时页面内提示；页面在后台时标题栏显示进度 | J30: node 测试 | K30: 请先阅读 AGENTS.md 和 docs/EcomCraft Architecture.zh-CN.md，遵守 EcomCraft 规则：客户端只提交模板 / 工作流 ID、服务端发布的参数白名单和各类 ID，不提交任意 ComfyUI JSON 或文件路径；生成只发往已登记的执行服务器（本机或局域网 ComfyUI），不向任何云端生成服务发送请求；接口遵守最小披露。用户可见文字走中英文翻译表；涉及的文档中英文同步更新。 任务：批量任务完成或失败时在页面内提示，并在页面处于后台时用 document.title 显示进度（如“(3/12) EcomCraft”）。不使用需要 HTTPS 的 Notification API。 完成后：运行相关测试，执行 git diff --check，按 ecomcraft-docs-sync 技能同步文档，并列出改动文件和你做过的验证。 | L30: 已完成 | M30: 2026-10-28
A31: 27 | B31: T47 | C31: MVP-C：易用与运维 | D31: F44 | E31: 一键诊断包 | F31: 新增管理接口 | G31: T36 | H31: M | I31: 管理员一键下载 zip：日志、服务器状态、版本与配置；自动去除密钥、密码、提示词、图片和会话信息 | J31: C# 测试脱敏规则 | K31: 请先阅读 AGENTS.md 和 docs/EcomCraft Architecture.zh-CN.md，遵守 EcomCraft 规则：客户端只提交模板 / 工作流 ID、服务端发布的参数白名单和各类 ID，不提交任意 ComfyUI JSON 或文件路径；生成只发往已登记的执行服务器（本机或局域网 ComfyUI），不向任何云端生成服务发送请求；接口遵守最小披露。用户可见文字走中英文翻译表；涉及的文档中英文同步更新。 任务：为管理员增加“下载诊断包”：包含最近日志、各执行服务器状态、版本信息和 EcomCraft 配置。必须去除 API Key、密码、提示词、用户图片和会话信息；服务器地址只在管理员下载时保留。先列出要包含的文件和脱敏规则让我确认。 请先进入计划模式给出设计方案（改哪些文件、数据结构、接口、风险），我确认后再实现。 完成后：运行相关测试，执行 git diff --check，按 ecomcraft-docs-sync 技能同步文档，并列出改动文件和你做过的验证。 | L31: 已完成 | M31: 2026-10-28
A32: 28 | B32: T48 | C32: MVP-C：易用与运维 | D32: F45 | E32: 系统数据备份与升级 | F32: 新增管理接口；中英文升级说明 | G32: T37 | H32: M | I32: 一键把 Data/EcomCraft 与账号数据备份为 zip；可从备份恢复；升级文档说明数据如何保留 | J32: 备份后在新目录恢复并验证 | K32: 请先阅读 AGENTS.md 和 docs/EcomCraft Architecture.zh-CN.md，遵守 EcomCraft 规则：客户端只提交模板 / 工作流 ID、服务端发布的参数白名单和各类 ID，不提交任意 ComfyUI JSON 或文件路径；生成只发往已登记的执行服务器（本机或局域网 ComfyUI），不向任何云端生成服务发送请求；接口遵守最小披露。用户可见文字走中英文翻译表；涉及的文档中英文同步更新。 任务：为管理员增加系统数据备份与恢复（Data/EcomCraft、账号数据库等，不含作品文件），恢复前校验备份完整性并要求确认。编写中英文升级说明。备份过程不得修改原文件。 请先进入计划模式给出设计方案（改哪些文件、数据结构、接口、风险），我确认后再实现。 完成后：运行相关测试，执行 git diff --check，按 ecomcraft-docs-sync 技能同步文档，并列出改动文件和你做过的验证。 | L32: 已完成 | M32: 2026-10-28 | N32: 备份、恢复、防篡改与无确认拦截均已在本机服务实测
A33: 29 | B33: T49 | C33: MVP-C：易用与运维 | D33: F46 | E33: 磁盘空间监控 | F33: Studio/Storage/ | G33: T37 | H33: S | I33: 本机或作品库剩余空间低于阈值时管理员可见警告；严重不足时拒绝新任务并说明原因 | J33: C# 测试阈值判断 | K33: 请先阅读 AGENTS.md 和 docs/EcomCraft Architecture.zh-CN.md，遵守 EcomCraft 规则：客户端只提交模板 / 工作流 ID、服务端发布的参数白名单和各类 ID，不提交任意 ComfyUI JSON 或文件路径；生成只发往已登记的执行服务器（本机或局域网 ComfyUI），不向任何云端生成服务发送请求；接口遵守最小披露。用户可见文字走中英文翻译表；涉及的文档中英文同步更新。 任务：后台定期检查平台服务器本机和作品库位置的剩余空间，低于阈值（可配置）时在管理视图警告；严重不足时拒绝新的生成并给出白话提示。 完成后：运行相关测试，执行 git diff --check，按 ecomcraft-docs-sync 技能同步文档，并列出改动文件和你做过的验证。 | L33: 已完成 | M33: 2026-10-28
A34: 30 | B34: T16 | C34: MVP-C：易用与运维 | D34: F10 | E34: 中英文 README 与演示 | F34: README.md、README.en.md、docs/README.zh-CN.md、docs/README.md | G34: T04；T13 | H34: S | I34: README 顶部有效果对比图、演示视频和部署服务说明；中英文一致；不写未实现的功能 | J34: 人工检查 | K34: 请先阅读 AGENTS.md 和 docs/EcomCraft Architecture.zh-CN.md，遵守 EcomCraft 规则：客户端只提交模板 / 工作流 ID、服务端发布的参数白名单和各类 ID，不提交任意 ComfyUI JSON 或文件路径；生成只发往已登记的执行服务器（本机或局域网 ComfyUI），不向任何云端生成服务发送请求；接口遵守最小披露。用户可见文字走中英文翻译表；涉及的文档中英文同步更新。 任务：更新中英文 README 和 docs 索引：顶部加入效果对比图区块（图片稍后提供，先放占位）、演示视频链接位、联系方式与部署服务说明；功能列表按 MVP 实际完成情况更新，不写尚未实现的功能。 完成后：运行相关测试，执行 git diff --check，按 ecomcraft-docs-sync 技能同步文档，并列出改动文件和你做过的验证。 | L34: 已完成 | M34: 2026-10-28 | N34: 效果对比图与演示视频为占位，图片视频稍后提供
A35: 31 | B35: T30 | C35: 后续：功能增强 | D35: F25 | E35: 卖点分析与套图分镜 | F35: 提示词服务；新增分镜 API；分镜确认界面 | G35: T08；T38 | H35: L | I35: 上传商品后生成卖点列表与套图分镜（每张图对应模板、提示词片段和用途）；用户可增删改后一键批量生成 | J35: C# 测试分镜结构校验；node 测试确认界面 | K35: 请先阅读 AGENTS.md 和 docs/EcomCraft Architecture.zh-CN.md，遵守 EcomCraft 规则：客户端只提交模板 / 工作流 ID、服务端发布的参数白名单和各类 ID，不提交任意 ComfyUI JSON 或文件路径；生成只发往已登记的执行服务器（本机或局域网 ComfyUI），不向任何云端生成服务发送请求；接口遵守最小披露。用户可见文字走中英文翻译表；涉及的文档中英文同步更新。 任务：新增“卖点分析与套图分镜”。复用提示词服务：输入商品描述（及可选的用户卖点），输出结构化分镜（每一项 = 模板 ID + 提示词片段 + 用途说明）。服务端必须把分镜的每一项再经模板与白名单校验，不能让模型输出直接变成任意参数。工作台展示分镜供用户确认和修改，确认后交给套图与批量。 请先进入计划模式给出设计方案（改哪些文件、数据结构、接口、风险），我确认后再实现。 完成后：运行相关测试，执行 git diff --check，按 ecomcraft-docs-sync 技能同步文档，并列出改动文件和你做过的验证。 | L35: 未开始 | N35: MVP 后优先
A36: 32 | B36: T05 | C36: 后续：功能增强 | D36: F19 | E36: 品类预设 | F36: Studio/Templates/（categories 合并逻辑）；品类选择 | G36: T04 | H36: M | I36: 参数合并顺序为“模板默认 < 品类预设 < 用户输入”，结果全部经白名单校验；界面可选品类 | J36: C# 测试合并顺序与越界拒绝；node 测试界面 | K36: 请先阅读 AGENTS.md 和 docs/EcomCraft Architecture.zh-CN.md，遵守 EcomCraft 规则：客户端只提交模板 / 工作流 ID、服务端发布的参数白名单和各类 ID，不提交任意 ComfyUI JSON 或文件路径；生成只发往已登记的执行服务器（本机或局域网 ComfyUI），不向任何云端生成服务发送请求；接口遵守最小披露。用户可见文字走中英文翻译表；涉及的文档中英文同步更新。 任务：实现模板的品类预设。模板的 categories 中每个品类可覆盖部分参数与提示词片段（如光线、背景描述）。合并顺序：模板默认 < 品类预设 < 用户输入，合并结果仍须经白名单校验。品类名称中英文齐全。 请先进入计划模式给出设计方案（改哪些文件、数据结构、接口、风险），我确认后再实现。 完成后：运行相关测试，执行 git diff --check，按 ecomcraft-docs-sync 技能同步文档，并列出改动文件和你做过的验证。 | L36: 未开始
A37: 33 | B37: T17 | C37: 后续：功能增强 | D37: F12 | E37: 品牌资料包 | F37: 新增品牌资料包存储与 API；模板 brand_kit 槽位；管理界面 | G37: T02；T37 | H37: L | I37: 可创建品牌资料包（Logo、品牌色、偏好背景、参考图）；生成时模板自动使用所选资料包；资料包按用户或团队隔离 | J37: C# 测试隔离与校验；本机生成验证 | K37: 请先阅读 AGENTS.md 和 docs/EcomCraft Architecture.zh-CN.md，遵守 EcomCraft 规则：客户端只提交模板 / 工作流 ID、服务端发布的参数白名单和各类 ID，不提交任意 ComfyUI JSON 或文件路径；生成只发往已登记的执行服务器（本机或局域网 ComfyUI），不向任何云端生成服务发送请求；接口遵守最小披露。用户可见文字走中英文翻译表；涉及的文档中英文同步更新。 任务：实现品牌资料包：保存 Logo、品牌色、偏好背景描述和若干风格参考图；生成时模板的 brand_kit 槽位把资料包内容映射到工作流的白名单参数（如参考图输入、提示词片段）。客户端只提交资料包 ID，不得直接提交图片路径。 请先进入计划模式给出设计方案（改哪些文件、数据结构、接口、风险），我确认后再实现。 完成后：运行相关测试，执行 git diff --check，按 ecomcraft-docs-sync 技能同步文档，并列出改动文件和你做过的验证。 | L37: 未开始
A38: 34 | B38: T09 | C38: 后续：功能增强 | D38: F04 | E38: 项目归档：服务端存储与 API | F38: 新增项目存储与 API；更新 AGENTS.md 相关规则 | G38: T35；T37 | H38: L | I38: 可创建、重命名、删除项目；作品可归入项目；重启后仍在；平台内只能看到自己的项目 | J38: C# 测试用户隔离与删除 | K38: 请先阅读 AGENTS.md 和 docs/EcomCraft Architecture.zh-CN.md，遵守 EcomCraft 规则：客户端只提交模板 / 工作流 ID、服务端发布的参数白名单和各类 ID，不提交任意 ComfyUI JSON 或文件路径；生成只发往已登记的执行服务器（本机或局域网 ComfyUI），不向任何云端生成服务发送请求；接口遵守最小披露。用户可见文字走中英文翻译表；涉及的文档中英文同步更新。 任务：在现有画廊和作品索引之上增加“项目”：一个项目对应一个客户或一批商品，作品可归入项目，记录模板、参数、种子和执行服务器。平台内按用户隔离，用户可删除自己的记录。AGENTS.md 规定进度观测不得长期保存提示词——本功能是用户主动保存的作品记录，请在方案中说明边界，并在 AGENTS.md 中补充对应规则。 请先进入计划模式给出设计方案（改哪些文件、数据结构、接口、风险），我确认后再实现。 完成后：运行相关测试，执行 git diff --check，按 ecomcraft-docs-sync 技能同步文档，并列出改动文件和你做过的验证。 | L38: 未开始 | N38: 会修改 AGENTS.md 规则，务必审阅
A39: 35 | B39: T10 | C39: 后续：功能增强 | D39: F04 | E39: 项目归档：工作台界面 | F39: studio.js、index.html、studio.css | G39: T09 | H39: M | I39: 可切换当前项目；画廊可按项目筛选；“用相同参数重做”一键回填 | J39: node 测试 + 本机手动验证 | K39: 请先阅读 AGENTS.md 和 docs/EcomCraft Architecture.zh-CN.md，遵守 EcomCraft 规则：客户端只提交模板 / 工作流 ID、服务端发布的参数白名单和各类 ID，不提交任意 ComfyUI JSON 或文件路径；生成只发往已登记的执行服务器（本机或局域网 ComfyUI），不向任何云端生成服务发送请求；接口遵守最小披露。用户可见文字走中英文翻译表；涉及的文档中英文同步更新。 任务：在工作台加入项目选择器：切换当前项目、按项目查看作品、点击“用相同参数重做”回填模板、参数与种子。 请先进入计划模式给出设计方案（改哪些文件、数据结构、接口、风险），我确认后再实现。 完成后：运行相关测试，执行 git diff --check，按 ecomcraft-docs-sync 技能同步文档，并列出改动文件和你做过的验证。 | L39: 未开始
A40: 36 | B40: T50 | C40: 后续：功能增强 | D40: F47 | E40: 卖点图（固定版式文字） | F40: 新增版式模板；导出模块 | G40: T11 | H40: M | I40: 用户填写卖点文字后按固定版式排版到图上；文字由程序绘制，不由 AI 生成；中英文字体正常 | J40: C# 测试排版；人工检查中英文效果 | K40: 请先阅读 AGENTS.md 和 docs/EcomCraft Architecture.zh-CN.md，遵守 EcomCraft 规则：客户端只提交模板 / 工作流 ID、服务端发布的参数白名单和各类 ID，不提交任意 ComfyUI JSON 或文件路径；生成只发往已登记的执行服务器（本机或局域网 ComfyUI），不向任何云端生成服务发送请求；接口遵守最小披露。用户可见文字走中英文翻译表；涉及的文档中英文同步更新。 任务：实现卖点图：在生成的场景图上按固定版式叠加用户填写的标题和卖点文字（由服务端绘制，不由 AI 生成文字）。提供 2–3 个版式，字体需允许商用并同时支持中英文；先列出字体选择和许可让我确认。 请先进入计划模式给出设计方案（改哪些文件、数据结构、接口、风险），我确认后再实现。 完成后：运行相关测试，执行 git diff --check，按 ecomcraft-docs-sync 技能同步文档，并列出改动文件和你做过的验证。 | L40: 未开始
A41: 37 | B41: T51 | C41: 后续：功能增强 | D41: F48 | E41: 商品展示视频模板 | F41: 内置模板；画廊视频支持 | G41: T04；N02 | H41: L | I41: 商品展示视频模板可用；画廊和导出支持视频 | J41: 本机实际生成并检查 | K41: 请先阅读 AGENTS.md 和 docs/EcomCraft Architecture.zh-CN.md，遵守 EcomCraft 规则：客户端只提交模板 / 工作流 ID、服务端发布的参数白名单和各类 ID，不提交任意 ComfyUI JSON 或文件路径；生成只发往已登记的执行服务器（本机或局域网 ComfyUI），不向任何云端生成服务发送请求；接口遵守最小披露。用户可见文字走中英文翻译表；涉及的文档中英文同步更新。 任务：新增商品展示视频模板（工作流由外部专家制作），确认画廊、导出和存储对视频的支持，并评估各执行服务器的显存是否满足要求。 请先进入计划模式给出设计方案（改哪些文件、数据结构、接口、风险），我确认后再实现。 完成后：运行相关测试，执行 git diff --check，按 ecomcraft-docs-sync 技能同步文档，并列出改动文件和你做过的验证。 | L41: 未开始
...

Sheet 非开发事项
A1: 非开发事项
A2: 这些事需要你自己完成，部分开发任务依赖它们。
A4: 编号 | B4: 事项 | C4: 说明 | D4: 关联 | E4: 状态 | F4: 负责人 | G4: 备注
A5: N01 | B5: 选定可商用的基础模型 | C5: 优先评估指令编辑类模型；把“允许商用”作为第一条筛选标准，记录许可链接 | D5: S1 → T14 | E5: 未开始
A6: N02 | B6: 委托专家制作 4 个模板工作流 | C6: 白底主图、场景图、细节图、模特或手持图；必须同时输出商品蒙版；在 ComfyUI 社区或 Fiverr / Upwork 按单付费或分成合作 | D6: S2 → T04、T07 | E6: 未开始
A7: N03 | B7: 收集测试商品 | C7: 先在主攻品类收集约 15 个，再按“测试商品集”工作表的四类难点扩充到约 30 个 | D7: S3 → T06 | E7: 未开始
A8: N04 | B8: 制定付费定制服务价格 | C8: 标准模板覆盖不了的需求单独报价 | D8: S7 | E8: 暂缓 | G8: MVP 后再定
A9: N05 | B9: 开代做店验证需求 | C9: 闲鱼 / 淘宝 / Fiverr 挂出商品图代做服务 | D9: 获客与验证 | E9: 暂缓 | G9: 当前不考虑自己接单，改为 N07
A10: N06 | B10: 核对最新平台规范与合规细则 | C10: 开发前核对国内外平台的图片尺寸规范、亚马逊主图要求、欧盟 AI 法案的官方最新要求，必要时咨询律师 | D10: T11、T19、T20 | E10: 未开始
A11: N07 | B11: 种子团队试用 | C11: MVP 发布后找 3–5 个电商团队试用，记录问题与需求，决定后续优先级 | D11: 获客与验证 | E11: 未开始
A12: N08 | B12: 准备测试环境 | C12: 至少两台显卡电脑和一个 NAS 或共享文件夹，用于多机调度和存储实测 | D12: T33、T37 | E12: 未开始
A13: N09 | B13: 确定主攻品类 | C13: 选 1 个品类作为 MVP 模板调优的重点，并填入“品类预设矩阵” | D13: T04、T06 | E13: 未开始

Sheet 竞品分析
A1: 竞品分析（2026 年 10 月）
A2: 价格与功能来自公开资料，可能已变化；EcomGen、ecommerce-image-suite 数据来自第三方收录页。
A4: 竞品 | B4: 类型 | C4: 部署方式 | D4: 价格 | E4: 主要优势 | F4: 主要短板 | G4: 对我们的启示 | H4: 来源
A5: ComfyUI App Mode / App Builder | B5: 上游官方 | C5: 本地与 Comfy Cloud 均可 | D5: 免费（本地） | E5: 官方出品、免费；一键把工作流变成只显示必要输入的简单界面；ComfyHub 社区共享应用；生态最大 | F5: 通用工具，没有电商专属能力（品类、品牌、批量 SKU、平台导出、合规、项目历史、团队审核） | G5: “给 ComfyUI 套简单界面”不再是卖点，必须靠电商专属功能区分；兼容其应用格式（F27） | H5: 查看来源
A6: EcomGen | B6: 开源同类 | C6: 自托管，本地优先；生图调用 OpenAI 兼容或 Gemini 接口 | D6: 开源（许可未注明） | E6: 面向个人卖家；25 个模板与可复用套图；商品像素保护；AI 分层导出 PNG/PSD；智能体生成分镜；审阅编辑与 ZIP 导出 | F6: 生图依赖外部接口，数据与成本仍在云端；未见团队权限与 ComfyUI 支持 | G6: 与 MVP-B（电商出图）高度重合，需加快；我们的差异是完全本地生成、局域网多机调度与团队协作；借鉴分镜与 PSD（F25、F26） | H6: 查看来源
A7: ecommerce-image-suite | B7: 开源同类 | C7: 本地运行脚本，生图调用通义、豆包、OpenAI 等接口 | D7: 开源（许可状态不清） | E7: 约 460 星；覆盖 9 类电商图（白底主图、材质特写、模特图、详情页等）；按国内外平台规格输出；商品图分析与卖点提炼 | F7: 命令行工具，无图形界面；必须有付费接口密钥 | G7: 说明“卖点分析 → 套图”需求真实存在；我们用本地模型 + 图形界面做得更易用 | H7: 查看来源
A8: Invoke | B8: 团队创作平台 | C8: 云端托管（开源社区版可本地） | D8: 专业版 $79/月（年付）或 $99/月；企业版面议 | E8: 专业版提供多用户、基于角色的权限、共享图片/工作流/模型；企业版有 SSO 与定制工作流服务 | F8: 通用创意平台，非电商专用 | G8: 我们团队版定价与功能的直接参照（F11、F16） | H8: 查看来源
A9: Photoroom | B9: 海外 SaaS | C9: 云端 | D9: Pro $7.99/月；Max $26.99/月；Ultra 约 $99/月起；API 约 $0.02–0.10/张 | E9: 价格低；批量编辑；1000+ 模板覆盖 Shopify、亚马逊与社媒尺寸；Shopify 直接发布与 SEO；手机端；API | F9: 积分与批量上限使实际成本难预测；复杂或反光商品场景易显假；大团队一致性控制较弱 | G9: 小卖家价格战打不赢；我们强调高出图量、私有数据和品类一致性 | H9: 查看来源
A10: Claid.ai | B10: 海外 SaaS | C10: 云端 + API | D10: 按积分；企业面议 | E10: 面向目录级量产；API 可串联抠图、放大、生成背景、阴影、图转视频等；服装平铺转模特 | F10: 简单任务单价高于 Photoroom；深度定制需走销售 | G10: 大客户需要“流水线”能力：批量 + 一致性 + 可编排，这正是模板 + 品类预设 + 批量的方向 | H10: 查看来源
A11: 美图设计室 | B11: 国内 SaaS | C11: 云端 | D11: 约 1.36 元/张（测评口径） | E11: 零门槛、界面友好、功能全；出图快 | F11: 结果偏模板化、辨识度较低 | G11: 国内小卖家市场已被低价工具覆盖 | H11: 查看来源
A12: LinkFox | B12: 国内 SaaS | C12: 云端 | D12: 测评未给出 | E12: 对话式生图；商品库批量管理；适合跨境大批量 | F12: 生成较慢；偏跨境 | G12: “商品库 + 批量管理”是大批量用户刚需，对应项目归档（F04） | H12: 查看来源
A13: 绘蛙 | B13: 国内 SaaS（阿里系） | C13: 云端 | D13: 限时免费（测评时） | E13: 一次生成十张以上详情套图；参考图风格模板减少调提示词；面料质感保持好 | F13: 菜单入口多，上手需时间 | G13: “参考图定风格”验证了品牌资料包思路（F12） | H13: 查看来源
A14: 潮际好麦 | B14: 国内 SaaS | C14: 云端 | D14: 约 1.4 元/张（测评口径） | E14: 服装模特图有特色；自动生成营销主题句 | F14: 出图数量少；非服装品类较弱 | G14: 垂直品类做深也能立足；可考虑先主攻一两个品类 | H14: 查看来源

Sheet 测试商品集
A1: 模板测试商品集（目标约 30 个）
A2: 先在主攻品类收集约 15 个（N03、N09），再按四类难点扩充到约 30 个；合计与进度自动计算。
A4: 难点类型 | B4: 示例商品 | C4: 为什么难 | D4: 计划数量 | E4: 已收集 | F4: 备注
A5: 反光 | B5: 首饰、电器 | C5: 高光与倒影容易被 AI 改坏 | D5: 8 | E5: 0
A6: 透明 | B6: 玻璃瓶、香水 | C6: 透光与背景融合难以保真 | D6: 8 | E6: 0
A7: 带文字 | B7: 包装盒 | C7: 文字和 Logo 容易被重绘变形 | D7: 8 | E7: 0
A8: 软质 | B8: 衣服、包 | C8: 形状易被改动，褶皱不自然 | D8: 6 | E8: 0
A9: 合计 | D9: =SUM(D5:D8) | E9: =SUM(E5:E8)
A10: 收集进度 | E10: =IF(D9=0,0,E9/D9)

Sheet 品类预设矩阵
A1: 模板 × 品类预设进度
A2: 每格从下拉选择进度；“待定”请改成你主攻的品类（N09）。MVP 先只调主攻品类，品类预设机制（F19）在 MVP 之后开发。
A4: 模板 \ 品类 | B4: 首饰 | C4: 化妆品 | D4: 服装 | E4: 电子产品 | F4: （待定） | G4: （待定） | H4: 已调好
A5: 白底主图 | B5: 未开始 | C5: 未开始 | D5: 未开始 | E5: 未开始 | F5: 未开始 | G5: 未开始 | H5: =COUNTIF(B5:G5,"已调好")
A6: 场景图 | B6: 未开始 | C6: 未开始 | D6: 未开始 | E6: 未开始 | F6: 未开始 | G6: 未开始 | H6: =COUNTIF(B6:G6,"已调好")
A7: 细节图 | B7: 未开始 | C7: 未开始 | D7: 未开始 | E7: 未开始 | F7: 未开始 | G7: 未开始 | H7: =COUNTIF(B7:G7,"已调好")
A8: 模特或手持图 | B8: 未开始 | C8: 未开始 | D8: 未开始 | E8: 未开始 | F8: 未开始 | G8: 未开始 | H8: =COUNTIF(B8:G8,"已调好")
A9: 商品展示视频（后续） | B9: 未开始 | C9: 未开始 | D9: 未开始 | E9: 未开始 | F9: 未开始 | G9: 未开始 | H9: =COUNTIF(B9:G9,"已调好")
A10: 合计 | H10: =SUM(H5:H9)
A11: 完成率 | H11: =H10/30

Sheet 阶段汇总
A1: 阶段汇总
A2: 全部自动计算。
A4: 阶段 | B4: 功能数 | C4: 开发任务数 | D4: 已完成任务 | E4: 进行中任务 | F4: 任务完成率 | G4: 收入来源
A5: MVP-A：平台底座 | B5: =COUNTIF(功能总表!$B$5:$B$200,A5) | C5: =COUNTIF(开发任务!$C$5:$C$200,A5) | D5: =COUNTIFS(开发任务!$C$5:$C$200,A5,开发任务!$L$5:$L$200,"已完成") | E5: =COUNTIFS(开发任务!$C$5:$C$200,A5,开发任务!$L$5:$L$200,"进行中") | F5: =IF(C5=0,0,D5/C5) | G5: 部署安装服务（一台或多台显卡电脑 + 局域网访问）
A6: MVP-B：电商出图 | B6: =COUNTIF(功能总表!$B$5:$B$200,A6) | C6: =COUNTIF(开发任务!$C$5:$C$200,A6) | D6: =COUNTIFS(开发任务!$C$5:$C$200,A6,开发任务!$L$5:$L$200,"已完成") | E6: =COUNTIFS(开发任务!$C$5:$C$200,A6,开发任务!$L$5:$L$200,"进行中") | F6: =IF(C6=0,0,D6/C6) | G6: 部署安装服务；种子团队试用（N07）
A7: MVP-C：易用与运维 | B7: =COUNTIF(功能总表!$B$5:$B$200,A7) | C7: =COUNTIF(开发任务!$C$5:$C$200,A7) | D7: =COUNTIFS(开发任务!$C$5:$C$200,A7,开发任务!$L$5:$L$200,"已完成") | E7: =COUNTIFS(开发任务!$C$5:$C$200,A7,开发任务!$L$5:$L$200,"进行中") | F7: =IF(C7=0,0,D7/C7) | G7: 部署安装服务、技术支持
A8: 后续：功能增强 | B8: =COUNTIF(功能总表!$B$5:$B$200,A8) | C8: =COUNTIF(开发任务!$C$5:$C$200,A8) | D8: =COUNTIFS(开发任务!$C$5:$C$200,A8,开发任务!$L$5:$L$200,"已完成") | E8: =COUNTIFS(开发任务!$C$5:$C$200,A8,开发任务!$L$5:$L$200,"进行中") | F8: =IF(C8=0,0,D8/C8) | G8: 付费模板包、定制服务
A9: 后续：团队与商业化 | B9: =COUNTIF(功能总表!$B$5:$B$200,A9) | C9: =COUNTIF(开发任务!$C$5:$C$200,A9) | D9: =COUNTIFS(开发任务!$C$5:$C$200,A9,开发任务!$L$5:$L$200,"已完成") | E9: =COUNTIFS(开发任务!$C$5:$C$200,A9,开发任务!$L$5:$L$200,"进行中") | F9: =IF(C9=0,0,D9/C9) | G9: 团队版年费授权
A10: 预留：云端与定制 | B10: =COUNTIF(功能总表!$B$5:$B$200,A10) | C10: =COUNTIF(开发任务!$C$5:$C$200,A10) | D10: =COUNTIFS(开发任务!$C$5:$C$200,A10,开发任务!$L$5:$L$200,"已完成") | E10: =COUNTIFS(开发任务!$C$5:$C$200,A10,开发任务!$L$5:$L$200,"进行中") | F10: =IF(C10=0,0,D10/C10) | G10: 云端额度、品牌模型训练
A11: 合计 | B11: =SUM(B5:B10) | C11: =SUM(C5:C10) | D11: =SUM(D5:D10) | E11: =SUM(E5:E10) | F11: =IF(C11=0,0,D11/C11)
A12: 其中 MVP（A + B + C） | B12: =SUM(B5:B7) | C12: =SUM(C5:C7) | D12: =SUM(D5:D7) | E12: =SUM(E5:E7) | F12: =IF(C12=0,0,D12/C12)

Sheet 暂不做
A1: 明确先不做的事
A4: 事项 | B4: 原因
A5: 面向小卖家的公开 SaaS | B5: 不与 Photoroom、美图等成熟产品正面竞争
A6: 积分和在线支付系统 | B6: 前期靠部署服务和团队版授权收费；将来云端额度先用团队预算和每人额度管理
A7: 水印预览等 SaaS 式限制 | B7: 本地工具没有这个需求，反而会损害开源版口碑
A8: 为每个客户单独搭工作流 | B8: 客户差异放进品类预设与品牌资料包，超出标准的作为付费定制
A9: MVP 阶段的云端生成 | B9: 保留执行方抽象和三段式流程；修订 AGENTS.md 规则并确认后再开发（F18）
A10: 自己接单验证需求 | B10: 当前不考虑；改为 MVP 发布后找种子团队试用（N07）
